Workbook
Name AllTeams: Settings!$B$9:$B$56
Name champ: #REF!
Name Champion: #REF!
Name db_fifarank: Settings!$B$9:$C$56
Name ExtraTeams: #REF!
Name FifaRank13_24: Settings!$G$9:$G$20
Name FifaRank25_36: Settings!$H$9:$H$18
Name FifaRank37Plus: Settings!$I$9:$I$32
Name Final: #REF!
Name finalas\: #REF!
Name gmt_delta: Settings!#REF!
Name GmtOffset: Settings!$C$4
Name Goals_Final: #REF!
Name Goals_Final_OT: #REF!
Name Goals_Quart: #REF!
Name Goals_Quart_OT: #REF!
Name Goals_Ro16: #REF!
Name Goals_Ro16_OT: #REF!
Name Goals_Semi: #REF!
Name GoalsSemi_OT: #REF!
Name HomeGoals: #REF!
Name ID_Home: #REF!
Name ID_Visitor: #REF!
Name itype: Settings!#REF!
Name lang: Settings!#REF!
Name lang_list: #REF!
Name lookup_3rd: #REF!
Name qfinal: #REF!
Name Quarterfinals: #REF!
Name Round_16: #REF!
Name round16: #REF!
Name Semifinals: #REF!
Name sfinal: #REF!
Name T: #REF!
Name tbl_lookup_3rd: #REF!
Name Teams: #REF!
Name Teams_Quart: #REF!
Name Teams_Ro16: #REF!
Name Teams_Semi: #REF!
Name TeamsFinal: #REF!
Name ThirdPlace: #REF!
Name VisitorsGoals: #REF!
Name WeakTeams: Settings!$I$9:$I$32
Name champ: #REF!
Name Champion: #REF!
Name ExtraTeams: #REF!
Name Final: #REF!
Name finalas\: #REF!
Name Goals_Final: #REF!
Name Goals_Final_OT: #REF!
Name Goals_Quart: #REF!
Name Goals_Quart_OT: #REF!
Name Goals_Ro16: #REF!
Name Goals_Ro16_OT: #REF!
Name Goals_Semi: #REF!
Name GoalsSemi_OT: #REF!
Name HomeGoals: #REF!
Name ID_Home: #REF!
Name ID_Visitor: #REF!
Name lang_list: #REF!

Sheet FIFA WC 2026
A1: FIFA WORLD CUP 2026
A2: ="Times shown in GMT" & IF(GmtOffset=0,"",IF(GmtOffset>0," + "&GmtOffset&"h"," "&GmtOffset&"h"))
A3: Group Stage | S3: Round of 32 | W3: Round of 16 | AA3: Quarterfinals | AE3: Semifinals | AI3: Final
S4: Team | T4: Score | U4: ET | V4: PEN | W4: Team | X4: Score | Y4: ET | Z4: PEN | AA4: Team | AB4: Score | AC4: ET | AD4: PEN | AE4: Team | AF4: Score | AG4: ET | AH4: PEN | AI4: Team | AJ4: Score | AK4: ET | AL4: PEN
A5: 1 | B5: =TEXT((46184)+(15+4+GmtOffset)/24,"ddd") | C5: =TEXT((46184)+(15+4+GmtOffset)/24,"mmm d, yyyy") | D5: =TEXT((46184)+(15+4+GmtOffset)/24,"h:mm") | E5: Mexico | F5: 2 | G5: 0 | H5: South Africa | I5: A | K5: Group A | S5: =IF((COUNTIF($F$5:$G$76,">=0")=144),IFERROR(INDEX($AP$81:$AP$92,1),"Runner-up A"),"Runner-up A")
A6: 2 | B6: =TEXT((46184)+(22+4+GmtOffset)/24,"ddd") | C6: =TEXT((46184)+(22+4+GmtOffset)/24,"mmm d, yyyy") | D6: =TEXT((46184)+(22+4+GmtOffset)/24,"h:mm") | E6: South Korea | F6: 2 | G6: 1 | H6: Czechia | I6: A | L6: PL | M6: W | N6: D | O6: L | P6: GF - GA | Q6: P | S6: =IF((COUNTIF($F$5:$G$76,">=0")=144),IFERROR(INDEX($AP$81:$AP$92,2),"Runner-up B"),"Runner-up B") | BD6: Mexico | BE6: {=SUMPRODUCT((((E5:E10=BD6)+(H5:H10=BD6))>0)*ISNUMBER(F5:F10)*ISNUMBER(G5:G10))} | BF6: {=SUMPRODUCT((E5:E10=BD6)*ISNUMBER(F5:F10)*ISNUMBER(G5:G10)*(F5:F10>G5:G10))+SUMPRODUCT((H5:H10=BD6)*ISNUMBER(F5:F10)*ISNUMBER(G5:G10)*(G5:G10>F5:F10))} | BG6: {=SUMPRODUCT((((E5:E10=BD6)+(H5:H10=BD6))>0)*ISNUMBER(F5:F10)*ISNUMBER(G5:G10)*(F5:F10=G5:G10))} | BH6: =BE6-BF6-BG6 | BI6: {=SUMPRODUCT((E5:E10=BD6)*IFERROR(F5:F10,0))+SUMPRODUCT((H5:H10=BD6)*IFERROR(G5:G10,0))} | BJ6: {=SUMPRODUCT((E5:E10=BD6)*IFERROR(G5:G10,0))+SUMPRODUCT((H5:H10=BD6)*IFERROR(F5:F10,0))} | BK6: =BF6*3+BG6 | BL6: =1+SUMPRODUCT(((BK$6:BK$9>BK6)+(BK$6:BK$9=BK6)*(BM$6:BM$9>BM6)+(BK$6:BK$9=BK6)*(BM$6:BM$9=BM6)*(BN$6:BN$9>BN6)+(BK$6:BK$9=BK6)*(BM$6:BM$9=BM6)*(BN$6:BN$9=BN6)*(BO$6:BO$9>BO6)+(BK$6:BK$9=BK6)*(BM$6:BM$9=BM6)*(BN$6:BN$9=BN6)*(BO$6:BO$9=BO6)*((BI$6:BI$9-BJ$6:BJ$9)>(BI6-BJ6))+(BK$6:BK$9=BK6)*(BM$6:BM$9=BM6)*(BN$6:BN$9=BN6)*(BO$6:BO$9=BO6)*((BI$6:BI$9-BJ$6:BJ$9)=(BI6-BJ6))*(BI$6:BI$9>BI6)+(BK$6:BK$9=BK6)*(BM$6:BM$9=BM6)*(BN$6:BN$9=BN6)*(BO$6:BO$9=BO6)*((BI$6:BI$9-BJ$6:BJ$9)=(BI6-BJ6))*(BI$6:BI$9=BI6)*(ROW(BK$6:BK$9)<ROW(BK6)))*1) | BM6: {=SUMPRODUCT((E$5:E$10=BD6)*ISNUMBER(F$5:F$10)*ISNUMBER(G$5:G$10)*COUNTIFS(BD$6:BD$9,H$5:H$10,BK$6:BK$9,BK6)*((F$5:F$10>G$5:G$10)*3+(F$5:F$10=G$5:G$10)))+SUMPRODUCT((H$5:H$10=BD6)*ISNUMBER(F$5:F$10)*ISNUMBER(G$5:G$10)*COUNTIFS(BD$6:BD$9,E$5:E$10,BK$6:BK$9,BK6)*((G$5:G$10>F$5:F$10)*3+(F$5:F$10=G$5:G$10)))} | BN6: {=SUMPRODUCT((E$5:E$10=BD6)*ISNUMBER(F$5:F$10)*ISNUMBER(G$5:G$10)*COUNTIFS(BD$6:BD$9,H$5:H$10,BK$6:BK$9,BK6)*(F$5:F$10-G$5:G$10))+SUMPRODUCT((H$5:H$10=BD6)*ISNUMBER(F$5:F$10)*ISNUMBER(G$5:G$10)*COUNTIFS(BD$6:BD$9,E$5:E$10,BK$6:BK$9,BK6)*(G$5:G$10-F$5:F$10))} | BO6: {=SUMPRODUCT((E$5:E$10=BD6)*ISNUMBER(F$5:F$10)*ISNUMBER(G$5:G$10)*COUNTIFS(BD$6:BD$9,H$5:H$10,BK$6:BK$9,BK6)*F$5:F$10)+SUMPRODUCT((H$5:H$10=BD6)*ISNUMBER(F$5:F$10)*ISNUMBER(G$5:G$10)*COUNTIFS(BD$6:BD$9,E$5:E$10,BK$6:BK$9,BK6)*G$5:G$10)}
A7: 3 | B7: =TEXT((46191)+(21+4+GmtOffset)/24,"ddd") | C7: =TEXT((46191)+(21+4+GmtOffset)/24,"mmm d, yyyy") | D7: =TEXT((46191)+(21+4+GmtOffset)/24,"h:mm") | E7: Mexico | H7: South Korea | I7: A | K7: =INDEX(BD6:BD9,MATCH(1,BL6:BL9,0)) | L7: =INDEX(BE6:BE9,MATCH(1,BL6:BL9,0)) | M7: =INDEX(BF6:BF9,MATCH(1,BL6:BL9,0)) | N7: =INDEX(BG6:BG9,MATCH(1,BL6:BL9,0)) | O7: =INDEX(BH6:BH9,MATCH(1,BL6:BL9,0)) | P7: =INDEX(BI6:BI9,MATCH(1,BL6:BL9,0))&" - "&INDEX(BJ6:BJ9,MATCH(1,BL6:BL9,0)) | Q7: =INDEX(BK6:BK9,MATCH(1,BL6:BL9,0)) | W7: =IF(AND(ISNUMBER(T9),ISNUMBER(T10)),IF(T9>T10,S9,IF(T10>T9,S10,IF(NOT(AND(ISNUMBER(U9),ISNUMBER(U10))),"",IF(U9>U10,S9,IF(U10>U9,S10,IF(NOT(AND(ISNUMBER(V9),ISNUMBER(V10))),"",IF(V9>V10,S9,IF(V10>V9,S10,"")))))))),"W74") | BD7: South Africa | BE7: {=SUMPRODUCT((((E5:E10=BD7)+(H5:H10=BD7))>0)*ISNUMBER(F5:F10)*ISNUMBER(G5:G10))} | BF7: {=SUMPRODUCT((E5:E10=BD7)*ISNUMBER(F5:F10)*ISNUMBER(G5:G10)*(F5:F10>G5:G10))+SUMPRODUCT((H5:H10=BD7)*ISNUMBER(F5:F10)*ISNUMBER(G5:G10)*(G5:G10>F5:F10))} | BG7: {=SUMPRODUCT((((E5:E10=BD7)+(H5:H10=BD7))>0)*ISNUMBER(F5:F10)*ISNUMBER(G5:G10)*(F5:F10=G5:G10))} | BH7: =BE7-BF7-BG7 | BI7: {=SUMPRODUCT((E5:E10=BD7)*IFERROR(F5:F10,0))+SUMPRODUCT((H5:H10=BD7)*IFERROR(G5:G10,0))} | BJ7: {=SUMPRODUCT((E5:E10=BD7)*IFERROR(G5:G10,0))+SUMPRODUCT((H5:H10=BD7)*IFERROR(F5:F10,0))} | BK7: =BF7*3+BG7 | BL7: =1+SUMPRODUCT(((BK$6:BK$9>BK7)+(BK$6:BK$9=BK7)*(BM$6:BM$9>BM7)+(BK$6:BK$9=BK7)*(BM$6:BM$9=BM7)*(BN$6:BN$9>BN7)+(BK$6:BK$9=BK7)*(BM$6:BM$9=BM7)*(BN$6:BN$9=BN7)*(BO$6:BO$9>BO7)+(BK$6:BK$9=BK7)*(BM$6:BM$9=BM7)*(BN$6:BN$9=BN7)*(BO$6:BO$9=BO7)*((BI$6:BI$9-BJ$6:BJ$9)>(BI7-BJ7))+(BK$6:BK$9=BK7)*(BM$6:BM$9=BM7)*(BN$6:BN$9=BN7)*(BO$6:BO$9=BO7)*((BI$6:BI$9-BJ$6:BJ$9)=(BI7-BJ7))*(BI$6:BI$9>BI7)+(BK$6:BK$9=BK7)*(BM$6:BM$9=BM7)*(BN$6:BN$9=BN7)*(BO$6:BO$9=BO7)*((BI$6:BI$9-BJ$6:BJ$9)=(BI7-BJ7))*(BI$6:BI$9=BI7)*(ROW(BK$6:BK$9)<ROW(BK7)))*1) | BM7: {=SUMPRODUCT((E$5:E$10=BD7)*ISNUMBER(F$5:F$10)*ISNUMBER(G$5:G$10)*COUNTIFS(BD$6:BD$9,H$5:H$10,BK$6:BK$9,BK7)*((F$5:F$10>G$5:G$10)*3+(F$5:F$10=G$5:G$10)))+SUMPRODUCT((H$5:H$10=BD7)*ISNUMBER(F$5:F$10)*ISNUMBER(G$5:G$10)*COUNTIFS(BD$6:BD$9,E$5:E$10,BK$6:BK$9,BK7)*((G$5:G$10>F$5:F$10)*3+(F$5:F$10=G$5:G$10)))} | BN7: {=SUMPRODUCT((E$5:E$10=BD7)*ISNUMBER(F$5:F$10)*ISNUMBER(G$5:G$10)*COUNTIFS(BD$6:BD$9,H$5:H$10,BK$6:BK$9,BK7)*(F$5:F$10-G$5:G$10))+SUMPRODUCT((H$5:H$10=BD7)*ISNUMBER(F$5:F$10)*ISNUMBER(G$5:G$10)*COUNTIFS(BD$6:BD$9,E$5:E$10,BK$6:BK$9,BK7)*(G$5:G$10-F$5:F$10))} | BO7: {=SUMPRODUCT((E$5:E$10=BD7)*ISNUMBER(F$5:F$10)*ISNUMBER(G$5:G$10)*COUNTIFS(BD$6:BD$9,H$5:H$10,BK$6:BK$9,BK7)*F$5:F$10)+SUMPRODUCT((H$5:H$10=BD7)*ISNUMBER(F$5:F$10)*ISNUMBER(G$5:G$10)*COUNTIFS(BD$6:BD$9,E$5:E$10,BK$6:BK$9,BK7)*G$5:G$10)}
A8: 4 | B8: =TEXT((46191)+(12+4+GmtOffset)/24,"ddd") | C8: =TEXT((46191)+(12+4+GmtOffset)/24,"mmm d, yyyy") | D8: =TEXT((46191)+(12+4+GmtOffset)/24,"h:mm") | E8: Czechia | H8: South Africa | I8: A | K8: =INDEX(BD6:BD9,MATCH(2,BL6:BL9,0)) | L8: =INDEX(BE6:BE9,MATCH(2,BL6:BL9,0)) | M8: =INDEX(BF6:BF9,MATCH(2,BL6:BL9,0)) | N8: =INDEX(BG6:BG9,MATCH(2,BL6:BL9,0)) | O8: =INDEX(BH6:BH9,MATCH(2,BL6:BL9,0)) | P8: =INDEX(BI6:BI9,MATCH(2,BL6:BL9,0))&" - "&INDEX(BJ6:BJ9,MATCH(2,BL6:BL9,0)) | Q8: =INDEX(BK6:BK9,MATCH(2,BL6:BL9,0)) | W8: =IF(AND(ISNUMBER(T21),ISNUMBER(T22)),IF(T21>T22,S21,IF(T22>T21,S22,IF(NOT(AND(ISNUMBER(U21),ISNUMBER(U22))),"",IF(U21>U22,S21,IF(U22>U21,S22,IF(NOT(AND(ISNUMBER(V21),ISNUMBER(V22))),"",IF(V21>V22,S21,IF(V22>V21,S22,"")))))))),"W77") | BD8: South Korea | BE8: {=SUMPRODUCT((((E5:E10=BD8)+(H5:H10=BD8))>0)*ISNUMBER(F5:F10)*ISNUMBER(G5:G10))} | BF8: {=SUMPRODUCT((E5:E10=BD8)*ISNUMBER(F5:F10)*ISNUMBER(G5:G10)*(F5:F10>G5:G10))+SUMPRODUCT((H5:H10=BD8)*ISNUMBER(F5:F10)*ISNUMBER(G5:G10)*(G5:G10>F5:F10))} | BG8: {=SUMPRODUCT((((E5:E10=BD8)+(H5:H10=BD8))>0)*ISNUMBER(F5:F10)*ISNUMBER(G5:G10)*(F5:F10=G5:G10))} | BH8: =BE8-BF8-BG8 | BI8: {=SUMPRODUCT((E5:E10=BD8)*IFERROR(F5:F10,0))+SUMPRODUCT((H5:H10=BD8)*IFERROR(G5:G10,0))} | BJ8: {=SUMPRODUCT((E5:E10=BD8)*IFERROR(G5:G10,0))+SUMPRODUCT((H5:H10=BD8)*IFERROR(F5:F10,0))} | BK8: =BF8*3+BG8 | BL8: =1+SUMPRODUCT(((BK$6:BK$9>BK8)+(BK$6:BK$9=BK8)*(BM$6:BM$9>BM8)+(BK$6:BK$9=BK8)*(BM$6:BM$9=BM8)*(BN$6:BN$9>BN8)+(BK$6:BK$9=BK8)*(BM$6:BM$9=BM8)*(BN$6:BN$9=BN8)*(BO$6:BO$9>BO8)+(BK$6:BK$9=BK8)*(BM$6:BM$9=BM8)*(BN$6:BN$9=BN8)*(BO$6:BO$9=BO8)*((BI$6:BI$9-BJ$6:BJ$9)>(BI8-BJ8))+(BK$6:BK$9=BK8)*(BM$6:BM$9=BM8)*(BN$6:BN$9=BN8)*(BO$6:BO$9=BO8)*((BI$6:BI$9-BJ$6:BJ$9)=(BI8-BJ8))*(BI$6:BI$9>BI8)+(BK$6:BK$9=BK8)*(BM$6:BM$9=BM8)*(BN$6:BN$9=BN8)*(BO$6:BO$9=BO8)*((BI$6:BI$9-BJ$6:BJ$9)=(BI8-BJ8))*(BI$6:BI$9=BI8)*(ROW(BK$6:BK$9)<ROW(BK8)))*1) | BM8: {=SUMPRODUCT((E$5:E$10=BD8)*ISNUMBER(F$5:F$10)*ISNUMBER(G$5:G$10)*COUNTIFS(BD$6:BD$9,H$5:H$10,BK$6:BK$9,BK8)*((F$5:F$10>G$5:G$10)*3+(F$5:F$10=G$5:G$10)))+SUMPRODUCT((H$5:H$10=BD8)*ISNUMBER(F$5:F$10)*ISNUMBER(G$5:G$10)*COUNTIFS(BD$6:BD$9,E$5:E$10,BK$6:BK$9,BK8)*((G$5:G$10>F$5:F$10)*3+(F$5:F$10=G$5:G$10)))} | BN8: {=SUMPRODUCT((E$5:E$10=BD8)*ISNUMBER(F$5:F$10)*ISNUMBER(G$5:G$10)*COUNTIFS(BD$6:BD$9,H$5:H$10,BK$6:BK$9,BK8)*(F$5:F$10-G$5:G$10))+SUMPRODUCT((H$5:H$10=BD8)*ISNUMBER(F$5:F$10)*ISNUMBER(G$5:G$10)*COUNTIFS(BD$6:BD$9,E$5:E$10,BK$6:BK$9,BK8)*(G$5:G$10-F$5:F$10))} | BO8: {=SUMPRODUCT((E$5:E$10=BD8)*ISNUMBER(F$5:F$10)*ISNUMBER(G$5:G$10)*COUNTIFS(BD$6:BD$9,H$5:H$10,BK$6:BK$9,BK8)*F$5:F$10)+SUMPRODUCT((H$5:H$10=BD8)*ISNUMBER(F$5:F$10)*ISNUMBER(G$5:G$10)*COUNTIFS(BD$6:BD$9,E$5:E$10,BK$6:BK$9,BK8)*G$5:G$10)}
A9: 5 | B9: =TEXT((46197)+(21+4+GmtOffset)/24,"ddd") | C9: =TEXT((46197)+(21+4+GmtOffset)/24,"mmm d, yyyy") | D9: =TEXT((46197)+(21+4+GmtOffset)/24,"h:mm") | E9: Czechia | H9: Mexico | I9: A | K9: =INDEX(BD6:BD9,MATCH(3,BL6:BL9,0)) | L9: =INDEX(BE6:BE9,MATCH(3,BL6:BL9,0)) | M9: =INDEX(BF6:BF9,MATCH(3,BL6:BL9,0)) | N9: =INDEX(BG6:BG9,MATCH(3,BL6:BL9,0)) | O9: =INDEX(BH6:BH9,MATCH(3,BL6:BL9,0)) | P9: =INDEX(BI6:BI9,MATCH(3,BL6:BL9,0))&" - "&INDEX(BJ6:BJ9,MATCH(3,BL6:BL9,0)) | Q9: =INDEX(BK6:BK9,MATCH(3,BL6:BL9,0)) | S9: =IF((COUNTIF($F$5:$G$76,">=0")=144),IFERROR(INDEX($AO$81:$AO$92,5),"Winner E"),"Winner E") | BD9: Czechia | BE9: {=SUMPRODUCT((((E5:E10=BD9)+(H5:H10=BD9))>0)*ISNUMBER(F5:F10)*ISNUMBER(G5:G10))} | BF9: {=SUMPRODUCT((E5:E10=BD9)*ISNUMBER(F5:F10)*ISNUMBER(G5:G10)*(F5:F10>G5:G10))+SUMPRODUCT((H5:H10=BD9)*ISNUMBER(F5:F10)*ISNUMBER(G5:G10)*(G5:G10>F5:F10))} | BG9: {=SUMPRODUCT((((E5:E10=BD9)+(H5:H10=BD9))>0)*ISNUMBER(F5:F10)*ISNUMBER(G5:G10)*(F5:F10=G5:G10))} | BH9: =BE9-BF9-BG9 | BI9: {=SUMPRODUCT((E5:E10=BD9)*IFERROR(F5:F10,0))+SUMPRODUCT((H5:H10=BD9)*IFERROR(G5:G10,0))} | BJ9: {=SUMPRODUCT((E5:E10=BD9)*IFERROR(G5:G10,0))+SUMPRODUCT((H5:H10=BD9)*IFERROR(F5:F10,0))} | BK9: =BF9*3+BG9 | BL9: =1+SUMPRODUCT(((BK$6:BK$9>BK9)+(BK$6:BK$9=BK9)*(BM$6:BM$9>BM9)+(BK$6:BK$9=BK9)*(BM$6:BM$9=BM9)*(BN$6:BN$9>BN9)+(BK$6:BK$9=BK9)*(BM$6:BM$9=BM9)*(BN$6:BN$9=BN9)*(BO$6:BO$9>BO9)+(BK$6:BK$9=BK9)*(BM$6:BM$9=BM9)*(BN$6:BN$9=BN9)*(BO$6:BO$9=BO9)*((BI$6:BI$9-BJ$6:BJ$9)>(BI9-BJ9))+(BK$6:BK$9=BK9)*(BM$6:BM$9=BM9)*(BN$6:BN$9=BN9)*(BO$6:BO$9=BO9)*((BI$6:BI$9-BJ$6:BJ$9)=(BI9-BJ9))*(BI$6:BI$9>BI9)+(BK$6:BK$9=BK9)*(BM$6:BM$9=BM9)*(BN$6:BN$9=BN9)*(BO$6:BO$9=BO9)*((BI$6:BI$9-BJ$6:BJ$9)=(BI9-BJ9))*(BI$6:BI$9=BI9)*(ROW(BK$6:BK$9)<ROW(BK9)))*1) | BM9: {=SUMPRODUCT((E$5:E$10=BD9)*ISNUMBER(F$5:F$10)*ISNUMBER(G$5:G$10)*COUNTIFS(BD$6:BD$9,H$5:H$10,BK$6:BK$9,BK9)*((F$5:F$10>G$5:G$10)*3+(F$5:F$10=G$5:G$10)))+SUMPRODUCT((H$5:H$10=BD9)*ISNUMBER(F$5:F$10)*ISNUMBER(G$5:G$10)*COUNTIFS(BD$6:BD$9,E$5:E$10,BK$6:BK$9,BK9)*((G$5:G$10>F$5:F$10)*3+(F$5:F$10=G$5:G$10)))} | BN9: {=SUMPRODUCT((E$5:E$10=BD9)*ISNUMBER(F$5:F$10)*ISNUMBER(G$5:G$10)*COUNTIFS(BD$6:BD$9,H$5:H$10,BK$6:BK$9,BK9)*(F$5:F$10-G$5:G$10))+SUMPRODUCT((H$5:H$10=BD9)*ISNUMBER(F$5:F$10)*ISNUMBER(G$5:G$10)*COUNTIFS(BD$6:BD$9,E$5:E$10,BK$6:BK$9,BK9)*(G$5:G$10-F$5:F$10))} | BO9: {=SUMPRODUCT((E$5:E$10=BD9)*ISNUMBER(F$5:F$10)*ISNUMBER(G$5:G$10)*COUNTIFS(BD$6:BD$9,H$5:H$10,BK$6:BK$9,BK9)*F$5:F$10)+SUMPRODUCT((H$5:H$10=BD9)*ISNUMBER(F$5:F$10)*ISNUMBER(G$5:G$10)*COUNTIFS(BD$6:BD$9,E$5:E$10,BK$6:BK$9,BK9)*G$5:G$10)}
A10: 6 | B10: =TEXT((46197)+(21+4+GmtOffset)/24,"ddd") | C10: =TEXT((46197)+(21+4+GmtOffset)/24,"mmm d, yyyy") | D10: =TEXT((46197)+(21+4+GmtOffset)/24,"h:mm") | E10: South Africa | H10: South Korea | I10: A | K10: =INDEX(BD6:BD9,MATCH(4,BL6:BL9,0)) | L10: =INDEX(BE6:BE9,MATCH(4,BL6:BL9,0)) | M10: =INDEX(BF6:BF9,MATCH(4,BL6:BL9,0)) | N10: =INDEX(BG6:BG9,MATCH(4,BL6:BL9,0)) | O10: =INDEX(BH6:BH9,MATCH(4,BL6:BL9,0)) | P10: =INDEX(BI6:BI9,MATCH(4,BL6:BL9,0))&" - "&INDEX(BJ6:BJ9,MATCH(4,BL6:BL9,0)) | Q10: =INDEX(BK6:BK9,MATCH(4,BL6:BL9,0)) | S10: =IF((COUNTIF($F$5:$G$76,">=0")=144),IFERROR(INDEX($AQ$81:$AQ$92,MATCH($BM$81,$AN$81:$AN$92,0)),"Best 3rd A/B/C/D/F"),"Best 3rd A/B/C/D/F")
A11: 7 | B11: =TEXT((46185)+(15+4+GmtOffset)/24,"ddd") | C11: =TEXT((46185)+(15+4+GmtOffset)/24,"mmm d, yyyy") | D11: =TEXT((46185)+(15+4+GmtOffset)/24,"h:mm") | E11: Canada | F11: 1 | G11: 1 | H11: Bosnia & Herzegovina | I11: B | K11: Group B | AA11: =IF(AND(ISNUMBER(X7),ISNUMBER(X8)),IF(X7>X8,W7,IF(X8>X7,W8,IF(NOT(AND(ISNUMBER(Y7),ISNUMBER(Y8))),"",IF(Y7>Y8,W7,IF(Y8>Y7,W8,IF(NOT(AND(ISNUMBER(Z7),ISNUMBER(Z8))),"",IF(Z7>Z8,W7,IF(Z8>Z7,W8,"")))))))),"W89")
A12: 8 | B12: =TEXT((46186)+(15+4+GmtOffset)/24,"ddd") | C12: =TEXT((46186)+(15+4+GmtOffset)/24,"mmm d, yyyy") | D12: =TEXT((46186)+(15+4+GmtOffset)/24,"h:mm") | E12: Qatar | H12: Switzerland | I12: B | L12: PL | M12: W | N12: D | O12: L | P12: GF - GA | Q12: P | AA12: =IF(AND(ISNUMBER(X15),ISNUMBER(X16)),IF(X15>X16,W15,IF(X16>X15,W16,IF(NOT(AND(ISNUMBER(Y15),ISNUMBER(Y16))),"",IF(Y15>Y16,W15,IF(Y16>Y15,W16,IF(NOT(AND(ISNUMBER(Z15),ISNUMBER(Z16))),"",IF(Z15>Z16,W15,IF(Z16>Z15,W16,"")))))))),"W90") | BD12: Canada | BE12: {=SUMPRODUCT((((E11:E16=BD12)+(H11:H16=BD12))>0)*ISNUMBER(F11:F16)*ISNUMBER(G11:G16))} | BF12: {=SUMPRODUCT((E11:E16=BD12)*ISNUMBER(F11:F16)*ISNUMBER(G11:G16)*(F11:F16>G11:G16))+SUMPRODUCT((H11:H16=BD12)*ISNUMBER(F11:F16)*ISNUMBER(G11:G16)*(G11:G16>F11:F16))} | BG12: {=SUMPRODUCT((((E11:E16=BD12)+(H11:H16=BD12))>0)*ISNUMBER(F11:F16)*ISNUMBER(G11:G16)*(F11:F16=G11:G16))} | BH12: =BE12-BF12-BG12 | BI12: {=SUMPRODUCT((E11:E16=BD12)*IFERROR(F11:F16,0))+SUMPRODUCT((H11:H16=BD12)*IFERROR(G11:G16,0))} | BJ12: {=SUMPRODUCT((E11:E16=BD12)*IFERROR(G11:G16,0))+SUMPRODUCT((H11:H16=BD12)*IFERROR(F11:F16,0))} | BK12: =BF12*3+BG12 | BL12: =1+SUMPRODUCT(((BK$12:BK$15>BK12)+(BK$12:BK$15=BK12)*(BM$12:BM$15>BM12)+(BK$12:BK$15=BK12)*(BM$12:BM$15=BM12)*(BN$12:BN$15>BN12)+(BK$12:BK$15=BK12)*(BM$12:BM$15=BM12)*(BN$12:BN$15=BN12)*(BO$12:BO$15>BO12)+(BK$12:BK$15=BK12)*(BM$12:BM$15=BM12)*(BN$12:BN$15=BN12)*(BO$12:BO$15=BO12)*((BI$12:BI$15-BJ$12:BJ$15)>(BI12-BJ12))+(BK$12:BK$15=BK12)*(BM$12:BM$15=BM12)*(BN$12:BN$15=BN12)*(BO$12:BO$15=BO12)*((BI$12:BI$15-BJ$12:BJ$15)=(BI12-BJ12))*(BI$12:BI$15>BI12)+(BK$12:BK$15=BK12)*(BM$12:BM$15=BM12)*(BN$12:BN$15=BN12)*(BO$12:BO$15=BO12)*((BI$12:BI$15-BJ$12:BJ$15)=(BI12-BJ12))*(BI$12:BI$15=BI12)*(ROW(BK$12:BK$15)<ROW(BK12)))*1) | BM12: {=SUMPRODUCT((E$11:E$16=BD12)*ISNUMBER(F$11:F$16)*ISNUMBER(G$11:G$16)*COUNTIFS(BD$12:BD$15,H$11:H$16,BK$12:BK$15,BK12)*((F$11:F$16>G$11:G$16)*3+(F$11:F$16=G$11:G$16)))+SUMPRODUCT((H$11:H$16=BD12)*ISNUMBER(F$11:F$16)*ISNUMBER(G$11:G$16)*COUNTIFS(BD$12:BD$15,E$11:E$16,BK$12:BK$15,BK12)*((G$11:G$16>F$11:F$16)*3+(F$11:F$16=G$11:G$16)))} | BN12: {=SUMPRODUCT((E$11:E$16=BD12)*ISNUMBER(F$11:F$16)*ISNUMBER(G$11:G$16)*COUNTIFS(BD$12:BD$15,H$11:H$16,BK$12:BK$15,BK12)*(F$11:F$16-G$11:G$16))+SUMPRODUCT((H$11:H$16=BD12)*ISNUMBER(F$11:F$16)*ISNUMBER(G$11:G$16)*COUNTIFS(BD$12:BD$15,E$11:E$16,BK$12:BK$15,BK12)*(G$11:G$16-F$11:F$16))} | BO12: {=SUMPRODUCT((E$11:E$16=BD12)*ISNUMBER(F$11:F$16)*ISNUMBER(G$11:G$16)*COUNTIFS(BD$12:BD$15,H$11:H$16,BK$12:BK$15,BK12)*F$11:F$16)+SUMPRODUCT((H$11:H$16=BD12)*ISNUMBER(F$11:F$16)*ISNUMBER(G$11:G$16)*COUNTIFS(BD$12:BD$15,E$11:E$16,BK$12:BK$15,BK12)*G$11:G$16)}
A13: 9 | B13: =TEXT((46191)+(18+4+GmtOffset)/24,"ddd") | C13: =TEXT((46191)+(18+4+GmtOffset)/24,"mmm d, yyyy") | D13: =TEXT((46191)+(18+4+GmtOffset)/24,"h:mm") | E13: Canada | H13: Qatar | I13: B | K13: =INDEX(BD12:BD15,MATCH(1,BL12:BL15,0)) | L13: =INDEX(BE12:BE15,MATCH(1,BL12:BL15,0)) | M13: =INDEX(BF12:BF15,MATCH(1,BL12:BL15,0)) | N13: =INDEX(BG12:BG15,MATCH(1,BL12:BL15,0)) | O13: =INDEX(BH12:BH15,MATCH(1,BL12:BL15,0)) | P13: =INDEX(BI12:BI15,MATCH(1,BL12:BL15,0))&" - "&INDEX(BJ12:BJ15,MATCH(1,BL12:BL15,0)) | Q13: =INDEX(BK12:BK15,MATCH(1,BL12:BL15,0)) | S13: =IF((COUNTIF($F$5:$G$76,">=0")=144),IFERROR(INDEX($AO$81:$AO$92,6),"Winner F"),"Winner F") | BD13: Bosnia & Herzegovina | BE13: {=SUMPRODUCT((((E11:E16=BD13)+(H11:H16=BD13))>0)*ISNUMBER(F11:F16)*ISNUMBER(G11:G16))} | BF13: {=SUMPRODUCT((E11:E16=BD13)*ISNUMBER(F11:F16)*ISNUMBER(G11:G16)*(F11:F16>G11:G16))+SUMPRODUCT((H11:H16=BD13)*ISNUMBER(F11:F16)*ISNUMBER(G11:G16)*(G11:G16>F11:F16))} | BG13: {=SUMPRODUCT((((E11:E16=BD13)+(H11:H16=BD13))>0)*ISNUMBER(F11:F16)*ISNUMBER(G11:G16)*(F11:F16=G11:G16))} | BH13: =BE13-BF13-BG13 | BI13: {=SUMPRODUCT((E11:E16=BD13)*IFERROR(F11:F16,0))+SUMPRODUCT((H11:H16=BD13)*IFERROR(G11:G16,0))} | BJ13: {=SUMPRODUCT((E11:E16=BD13)*IFERROR(G11:G16,0))+SUMPRODUCT((H11:H16=BD13)*IFERROR(F11:F16,0))} | BK13: =BF13*3+BG13 | BL13: =1+SUMPRODUCT(((BK$12:BK$15>BK13)+(BK$12:BK$15=BK13)*(BM$12:BM$15>BM13)+(BK$12:BK$15=BK13)*(BM$12:BM$15=BM13)*(BN$12:BN$15>BN13)+(BK$12:BK$15=BK13)*(BM$12:BM$15=BM13)*(BN$12:BN$15=BN13)*(BO$12:BO$15>BO13)+(BK$12:BK$15=BK13)*(BM$12:BM$15=BM13)*(BN$12:BN$15=BN13)*(BO$12:BO$15=BO13)*((BI$12:BI$15-BJ$12:BJ$15)>(BI13-BJ13))+(BK$12:BK$15=BK13)*(BM$12:BM$15=BM13)*(BN$12:BN$15=BN13)*(BO$12:BO$15=BO13)*((BI$12:BI$15-BJ$12:BJ$15)=(BI13-BJ13))*(BI$12:BI$15>BI13)+(BK$12:BK$15=BK13)*(BM$12:BM$15=BM13)*(BN$12:BN$15=BN13)*(BO$12:BO$15=BO13)*((BI$12:BI$15-BJ$12:BJ$15)=(BI13-BJ13))*(BI$12:BI$15=BI13)*(ROW(BK$12:BK$15)<ROW(BK13)))*1) | BM13: {=SUMPRODUCT((E$11:E$16=BD13)*ISNUMBER(F$11:F$16)*ISNUMBER(G$11:G$16)*COUNTIFS(BD$12:BD$15,H$11:H$16,BK$12:BK$15,BK13)*((F$11:F$16>G$11:G$16)*3+(F$11:F$16=G$11:G$16)))+SUMPRODUCT((H$11:H$16=BD13)*ISNUMBER(F$11:F$16)*ISNUMBER(G$11:G$16)*COUNTIFS(BD$12:BD$15,E$11:E$16,BK$12:BK$15,BK13)*((G$11:G$16>F$11:F$16)*3+(F$11:F$16=G$11:G$16)))} | BN13: {=SUMPRODUCT((E$11:E$16=BD13)*ISNUMBER(F$11:F$16)*ISNUMBER(G$11:G$16)*COUNTIFS(BD$12:BD$15,H$11:H$16,BK$12:BK$15,BK13)*(F$11:F$16-G$11:G$16))+SUMPRODUCT((H$11:H$16=BD13)*ISNUMBER(F$11:F$16)*ISNUMBER(G$11:G$16)*COUNTIFS(BD$12:BD$15,E$11:E$16,BK$12:BK$15,BK13)*(G$11:G$16-F$11:F$16))} | BO13: {=SUMPRODUCT((E$11:E$16=BD13)*ISNUMBER(F$11:F$16)*ISNUMBER(G$11:G$16)*COUNTIFS(BD$12:BD$15,H$11:H$16,BK$12:BK$15,BK13)*F$11:F$16)+SUMPRODUCT((H$11:H$16=BD13)*ISNUMBER(F$11:F$16)*ISNUMBER(G$11:G$16)*COUNTIFS(BD$12:BD$15,E$11:E$16,BK$12:BK$15,BK13)*G$11:G$16)}
A14: 10 | B14: =TEXT((46191)+(15+4+GmtOffset)/24,"ddd") | C14: =TEXT((46191)+(15+4+GmtOffset)/24,"mmm d, yyyy") | D14: =TEXT((46191)+(15+4+GmtOffset)/24,"h:mm") | E14: Switzerland | H14: Bosnia & Herzegovina | I14: B | K14: =INDEX(BD12:BD15,MATCH(2,BL12:BL15,0)) | L14: =INDEX(BE12:BE15,MATCH(2,BL12:BL15,0)) | M14: =INDEX(BF12:BF15,MATCH(2,BL12:BL15,0)) | N14: =INDEX(BG12:BG15,MATCH(2,BL12:BL15,0)) | O14: =INDEX(BH12:BH15,MATCH(2,BL12:BL15,0)) | P14: =INDEX(BI12:BI15,MATCH(2,BL12:BL15,0))&" - "&INDEX(BJ12:BJ15,MATCH(2,BL12:BL15,0)) | Q14: =INDEX(BK12:BK15,MATCH(2,BL12:BL15,0)) | S14: =IF((COUNTIF($F$5:$G$76,">=0")=144),IFERROR(INDEX($AP$81:$AP$92,3),"Runner-up C"),"Runner-up C") | BD14: Qatar | BE14: {=SUMPRODUCT((((E11:E16=BD14)+(H11:H16=BD14))>0)*ISNUMBER(F11:F16)*ISNUMBER(G11:G16))} | BF14: {=SUMPRODUCT((E11:E16=BD14)*ISNUMBER(F11:F16)*ISNUMBER(G11:G16)*(F11:F16>G11:G16))+SUMPRODUCT((H11:H16=BD14)*ISNUMBER(F11:F16)*ISNUMBER(G11:G16)*(G11:G16>F11:F16))} | BG14: {=SUMPRODUCT((((E11:E16=BD14)+(H11:H16=BD14))>0)*ISNUMBER(F11:F16)*ISNUMBER(G11:G16)*(F11:F16=G11:G16))} | BH14: =BE14-BF14-BG14 | BI14: {=SUMPRODUCT((E11:E16=BD14)*IFERROR(F11:F16,0))+SUMPRODUCT((H11:H16=BD14)*IFERROR(G11:G16,0))} | BJ14: {=SUMPRODUCT((E11:E16=BD14)*IFERROR(G11:G16,0))+SUMPRODUCT((H11:H16=BD14)*IFERROR(F11:F16,0))} | BK14: =BF14*3+BG14 | BL14: =1+SUMPRODUCT(((BK$12:BK$15>BK14)+(BK$12:BK$15=BK14)*(BM$12:BM$15>BM14)+(BK$12:BK$15=BK14)*(BM$12:BM$15=BM14)*(BN$12:BN$15>BN14)+(BK$12:BK$15=BK14)*(BM$12:BM$15=BM14)*(BN$12:BN$15=BN14)*(BO$12:BO$15>BO14)+(BK$12:BK$15=BK14)*(BM$12:BM$15=BM14)*(BN$12:BN$15=BN14)*(BO$12:BO$15=BO14)*((BI$12:BI$15-BJ$12:BJ$15)>(BI14-BJ14))+(BK$12:BK$15=BK14)*(BM$12:BM$15=BM14)*(BN$12:BN$15=BN14)*(BO$12:BO$15=BO14)*((BI$12:BI$15-BJ$12:BJ$15)=(BI14-BJ14))*(BI$12:BI$15>BI14)+(BK$12:BK$15=BK14)*(BM$12:BM$15=BM14)*(BN$12:BN$15=BN14)*(BO$12:BO$15=BO14)*((BI$12:BI$15-BJ$12:BJ$15)=(BI14-BJ14))*(BI$12:BI$15=BI14)*(ROW(BK$12:BK$15)<ROW(BK14)))*1) | BM14: {=SUMPRODUCT((E$11:E$16=BD14)*ISNUMBER(F$11:F$16)*ISNUMBER(G$11:G$16)*COUNTIFS(BD$12:BD$15,H$11:H$16,BK$12:BK$15,BK14)*((F$11:F$16>G$11:G$16)*3+(F$11:F$16=G$11:G$16)))+SUMPRODUCT((H$11:H$16=BD14)*ISNUMBER(F$11:F$16)*ISNUMBER(G$11:G$16)*COUNTIFS(BD$12:BD$15,E$11:E$16,BK$12:BK$15,BK14)*((G$11:G$16>F$11:F$16)*3+(F$11:F$16=G$11:G$16)))} | BN14: {=SUMPRODUCT((E$11:E$16=BD14)*ISNUMBER(F$11:F$16)*ISNUMBER(G$11:G$16)*COUNTIFS(BD$12:BD$15,H$11:H$16,BK$12:BK$15,BK14)*(F$11:F$16-G$11:G$16))+SUMPRODUCT((H$11:H$16=BD14)*ISNUMBER(F$11:F$16)*ISNUMBER(G$11:G$16)*COUNTIFS(BD$12:BD$15,E$11:E$16,BK$12:BK$15,BK14)*(G$11:G$16-F$11:F$16))} | BO14: {=SUMPRODUCT((E$11:E$16=BD14)*ISNUMBER(F$11:F$16)*ISNUMBER(G$11:G$16)*COUNTIFS(BD$12:BD$15,H$11:H$16,BK$12:BK$15,BK14)*F$11:F$16)+SUMPRODUCT((H$11:H$16=BD14)*ISNUMBER(F$11:F$16)*ISNUMBER(G$11:G$16)*COUNTIFS(BD$12:BD$15,E$11:E$16,BK$12:BK$15,BK14)*G$11:G$16)}
A15: 11 | B15: =TEXT((46197)+(15+4+GmtOffset)/24,"ddd") | C15: =TEXT((46197)+(15+4+GmtOffset)/24,"mmm d, yyyy") | D15: =TEXT((46197)+(15+4+GmtOffset)/24,"h:mm") | E15: Switzerland | H15: Canada | I15: B | K15: =INDEX(BD12:BD15,MATCH(3,BL12:BL15,0)) | L15: =INDEX(BE12:BE15,MATCH(3,BL12:BL15,0)) | M15: =INDEX(BF12:BF15,MATCH(3,BL12:BL15,0)) | N15: =INDEX(BG12:BG15,MATCH(3,BL12:BL15,0)) | O15: =INDEX(BH12:BH15,MATCH(3,BL12:BL15,0)) | P15: =INDEX(BI12:BI15,MATCH(3,BL12:BL15,0))&" - "&INDEX(BJ12:BJ15,MATCH(3,BL12:BL15,0)) | Q15: =INDEX(BK12:BK15,MATCH(3,BL12:BL15,0)) | W15: =IF(AND(ISNUMBER(T5),ISNUMBER(T6)),IF(T5>T6,S5,IF(T6>T5,S6,IF(NOT(AND(ISNUMBER(U5),ISNUMBER(U6))),"",IF(U5>U6,S5,IF(U6>U5,S6,IF(NOT(AND(ISNUMBER(V5),ISNUMBER(V6))),"",IF(V5>V6,S5,IF(V6>V5,S6,"")))))))),"W73") | BD15: Switzerland | BE15: {=SUMPRODUCT((((E11:E16=BD15)+(H11:H16=BD15))>0)*ISNUMBER(F11:F16)*ISNUMBER(G11:G16))} | BF15: {=SUMPRODUCT((E11:E16=BD15)*ISNUMBER(F11:F16)*ISNUMBER(G11:G16)*(F11:F16>G11:G16))+SUMPRODUCT((H11:H16=BD15)*ISNUMBER(F11:F16)*ISNUMBER(G11:G16)*(G11:G16>F11:F16))} | BG15: {=SUMPRODUCT((((E11:E16=BD15)+(H11:H16=BD15))>0)*ISNUMBER(F11:F16)*ISNUMBER(G11:G16)*(F11:F16=G11:G16))} | BH15: =BE15-BF15-BG15 | BI15: {=SUMPRODUCT((E11:E16=BD15)*IFERROR(F11:F16,0))+SUMPRODUCT((H11:H16=BD15)*IFERROR(G11:G16,0))} | BJ15: {=SUMPRODUCT((E11:E16=BD15)*IFERROR(G11:G16,0))+SUMPRODUCT((H11:H16=BD15)*IFERROR(F11:F16,0))} | BK15: =BF15*3+BG15 | BL15: =1+SUMPRODUCT(((BK$12:BK$15>BK15)+(BK$12:BK$15=BK15)*(BM$12:BM$15>BM15)+(BK$12:BK$15=BK15)*(BM$12:BM$15=BM15)*(BN$12:BN$15>BN15)+(BK$12:BK$15=BK15)*(BM$12:BM$15=BM15)*(BN$12:BN$15=BN15)*(BO$12:BO$15>BO15)+(BK$12:BK$15=BK15)*(BM$12:BM$15=BM15)*(BN$12:BN$15=BN15)*(BO$12:BO$15=BO15)*((BI$12:BI$15-BJ$12:BJ$15)>(BI15-BJ15))+(BK$12:BK$15=BK15)*(BM$12:BM$15=BM15)*(BN$12:BN$15=BN15)*(BO$12:BO$15=BO15)*((BI$12:BI$15-BJ$12:BJ$15)=(BI15-BJ15))*(BI$12:BI$15>BI15)+(BK$12:BK$15=BK15)*(BM$12:BM$15=BM15)*(BN$12:BN$15=BN15)*(BO$12:BO$15=BO15)*((BI$12:BI$15-BJ$12:BJ$15)=(BI15-BJ15))*(BI$12:BI$15=BI15)*(ROW(BK$12:BK$15)<ROW(BK15)))*1) | BM15: {=SUMPRODUCT((E$11:E$16=BD15)*ISNUMBER(F$11:F$16)*ISNUMBER(G$11:G$16)*COUNTIFS(BD$12:BD$15,H$11:H$16,BK$12:BK$15,BK15)*((F$11:F$16>G$11:G$16)*3+(F$11:F$16=G$11:G$16)))+SUMPRODUCT((H$11:H$16=BD15)*ISNUMBER(F$11:F$16)*ISNUMBER(G$11:G$16)*COUNTIFS(BD$12:BD$15,E$11:E$16,BK$12:BK$15,BK15)*((G$11:G$16>F$11:F$16)*3+(F$11:F$16=G$11:G$16)))} | BN15: {=SUMPRODUCT((E$11:E$16=BD15)*ISNUMBER(F$11:F$16)*ISNUMBER(G$11:G$16)*COUNTIFS(BD$12:BD$15,H$11:H$16,BK$12:BK$15,BK15)*(F$11:F$16-G$11:G$16))+SUMPRODUCT((H$11:H$16=BD15)*ISNUMBER(F$11:F$16)*ISNUMBER(G$11:G$16)*COUNTIFS(BD$12:BD$15,E$11:E$16,BK$12:BK$15,BK15)*(G$11:G$16-F$11:F$16))} | BO15: {=SUMPRODUCT((E$11:E$16=BD15)*ISNUMBER(F$11:F$16)*ISNUMBER(G$11:G$16)*COUNTIFS(BD$12:BD$15,H$11:H$16,BK$12:BK$15,BK15)*F$11:F$16)+SUMPRODUCT((H$11:H$16=BD15)*ISNUMBER(F$11:F$16)*ISNUMBER(G$11:G$16)*COUNTIFS(BD$12:BD$15,E$11:E$16,BK$12:BK$15,BK15)*G$11:G$16)}
A16: 12 | B16: =TEXT((46197)+(15+4+GmtOffset)/24,"ddd") | C16: =TEXT((46197)+(15+4+GmtOffset)/24,"mmm d, yyyy") | D16: =TEXT((46197)+(15+4+GmtOffset)/24,"h:mm") | E16: Bosnia & Herzegovina | H16: Qatar | I16: B | K16: =INDEX(BD12:BD15,MATCH(4,BL12:BL15,0)) | L16: =INDEX(BE12:BE15,MATCH(4,BL12:BL15,0)) | M16: =INDEX(BF12:BF15,MATCH(4,BL12:BL15,0)) | N16: =INDEX(BG12:BG15,MATCH(4,BL12:BL15,0)) | O16: =INDEX(BH12:BH15,MATCH(4,BL12:BL15,0)) | P16: =INDEX(BI12:BI15,MATCH(4,BL12:BL15,0))&" - "&INDEX(BJ12:BJ15,MATCH(4,BL12:BL15,0)) | Q16: =INDEX(BK12:BK15,MATCH(4,BL12:BL15,0)) | W16: =IF(AND(ISNUMBER(T13),ISNUMBER(T14)),IF(T13>T14,S13,IF(T14>T13,S14,IF(NOT(AND(ISNUMBER(U13),ISNUMBER(U14))),"",IF(U13>U14,S13,IF(U14>U13,S14,IF(NOT(AND(ISNUMBER(V13),ISNUMBER(V14))),"",IF(V13>V14,S13,IF(V14>V13,S14,"")))))))),"W75")
A17: 13 | B17: =TEXT((46186)+(18+4+GmtOffset)/24,"ddd") | C17: =TEXT((46186)+(18+4+GmtOffset)/24,"mmm d, yyyy") | D17: =TEXT((46186)+(18+4+GmtOffset)/24,"h:mm") | E17: Brazil | F17: 0 | G17: 2 | H17: Morocco | I17: C | K17: Group C | S17: =IF((COUNTIF($F$5:$G$76,">=0")=144),IFERROR(INDEX($AO$81:$AO$92,3),"Winner C"),"Winner C")
A18: 14 | B18: =TEXT((46186)+(21+4+GmtOffset)/24,"ddd") | C18: =TEXT((46186)+(21+4+GmtOffset)/24,"mmm d, yyyy") | D18: =TEXT((46186)+(21+4+GmtOffset)/24,"h:mm") | E18: Haiti | H18: Scotland | I18: C | L18: PL | M18: W | N18: D | O18: L | P18: GF - GA | Q18: P | S18: =IF((COUNTIF($F$5:$G$76,">=0")=144),IFERROR(INDEX($AP$81:$AP$92,6),"Runner-up F"),"Runner-up F") | BD18: Brazil | BE18: {=SUMPRODUCT((((E17:E22=BD18)+(H17:H22=BD18))>0)*ISNUMBER(F17:F22)*ISNUMBER(G17:G22))} | BF18: {=SUMPRODUCT((E17:E22=BD18)*ISNUMBER(F17:F22)*ISNUMBER(G17:G22)*(F17:F22>G17:G22))+SUMPRODUCT((H17:H22=BD18)*ISNUMBER(F17:F22)*ISNUMBER(G17:G22)*(G17:G22>F17:F22))} | BG18: {=SUMPRODUCT((((E17:E22=BD18)+(H17:H22=BD18))>0)*ISNUMBER(F17:F22)*ISNUMBER(G17:G22)*(F17:F22=G17:G22))} | BH18: =BE18-BF18-BG18 | BI18: {=SUMPRODUCT((E17:E22=BD18)*IFERROR(F17:F22,0))+SUMPRODUCT((H17:H22=BD18)*IFERROR(G17:G22,0))} | BJ18: {=SUMPRODUCT((E17:E22=BD18)*IFERROR(G17:G22,0))+SUMPRODUCT((H17:H22=BD18)*IFERROR(F17:F22,0))} | BK18: =BF18*3+BG18 | BL18: =1+SUMPRODUCT(((BK$18:BK$21>BK18)+(BK$18:BK$21=BK18)*(BM$18:BM$21>BM18)+(BK$18:BK$21=BK18)*(BM$18:BM$21=BM18)*(BN$18:BN$21>BN18)+(BK$18:BK$21=BK18)*(BM$18:BM$21=BM18)*(BN$18:BN$21=BN18)*(BO$18:BO$21>BO18)+(BK$18:BK$21=BK18)*(BM$18:BM$21=BM18)*(BN$18:BN$21=BN18)*(BO$18:BO$21=BO18)*((BI$18:BI$21-BJ$18:BJ$21)>(BI18-BJ18))+(BK$18:BK$21=BK18)*(BM$18:BM$21=BM18)*(BN$18:BN$21=BN18)*(BO$18:BO$21=BO18)*((BI$18:BI$21-BJ$18:BJ$21)=(BI18-BJ18))*(BI$18:BI$21>BI18)+(BK$18:BK$21=BK18)*(BM$18:BM$21=BM18)*(BN$18:BN$21=BN18)*(BO$18:BO$21=BO18)*((BI$18:BI$21-BJ$18:BJ$21)=(BI18-BJ18))*(BI$18:BI$21=BI18)*(ROW(BK$18:BK$21)<ROW(BK18)))*1) | BM18: {=SUMPRODUCT((E$17:E$22=BD18)*ISNUMBER(F$17:F$22)*ISNUMBER(G$17:G$22)*COUNTIFS(BD$18:BD$21,H$17:H$22,BK$18:BK$21,BK18)*((F$17:F$22>G$17:G$22)*3+(F$17:F$22=G$17:G$22)))+SUMPRODUCT((H$17:H$22=BD18)*ISNUMBER(F$17:F$22)*ISNUMBER(G$17:G$22)*COUNTIFS(BD$18:BD$21,E$17:E$22,BK$18:BK$21,BK18)*((G$17:G$22>F$17:F$22)*3+(F$17:F$22=G$17:G$22)))} | BN18: {=SUMPRODUCT((E$17:E$22=BD18)*ISNUMBER(F$17:F$22)*ISNUMBER(G$17:G$22)*COUNTIFS(BD$18:BD$21,H$17:H$22,BK$18:BK$21,BK18)*(F$17:F$22-G$17:G$22))+SUMPRODUCT((H$17:H$22=BD18)*ISNUMBER(F$17:F$22)*ISNUMBER(G$17:G$22)*COUNTIFS(BD$18:BD$21,E$17:E$22,BK$18:BK$21,BK18)*(G$17:G$22-F$17:F$22))} | BO18: {=SUMPRODUCT((E$17:E$22=BD18)*ISNUMBER(F$17:F$22)*ISNUMBER(G$17:G$22)*COUNTIFS(BD$18:BD$21,H$17:H$22,BK$18:BK$21,BK18)*F$17:F$22)+SUMPRODUCT((H$17:H$22=BD18)*ISNUMBER(F$17:F$22)*ISNUMBER(G$17:G$22)*COUNTIFS(BD$18:BD$21,E$17:E$22,BK$18:BK$21,BK18)*G$17:G$22)}
A19: 15 | B19: =TEXT((46192)+(20.5+4+GmtOffset)/24,"ddd") | C19: =TEXT((46192)+(20.5+4+GmtOffset)/24,"mmm d, yyyy") | D19: =TEXT((46192)+(20.5+4+GmtOffset)/24,"h:mm") | E19: Brazil | H19: Haiti | I19: C | K19: =INDEX(BD18:BD21,MATCH(1,BL18:BL21,0)) | L19: =INDEX(BE18:BE21,MATCH(1,BL18:BL21,0)) | M19: =INDEX(BF18:BF21,MATCH(1,BL18:BL21,0)) | N19: =INDEX(BG18:BG21,MATCH(1,BL18:BL21,0)) | O19: =INDEX(BH18:BH21,MATCH(1,BL18:BL21,0)) | P19: =INDEX(BI18:BI21,MATCH(1,BL18:BL21,0))&" - "&INDEX(BJ18:BJ21,MATCH(1,BL18:BL21,0)) | Q19: =INDEX(BK18:BK21,MATCH(1,BL18:BL21,0)) | AE19: =IF(AND(ISNUMBER(AB11),ISNUMBER(AB12)),IF(AB11>AB12,AA11,IF(AB12>AB11,AA12,IF(NOT(AND(ISNUMBER(AC11),ISNUMBER(AC12))),"",IF(AC11>AC12,AA11,IF(AC12>AC11,AA12,IF(NOT(AND(ISNUMBER(AD11),ISNUMBER(AD12))),"",IF(AD11>AD12,AA11,IF(AD12>AD11,AA12,"")))))))),"W97") | BD19: Morocco | BE19: {=SUMPRODUCT((((E17:E22=BD19)+(H17:H22=BD19))>0)*ISNUMBER(F17:F22)*ISNUMBER(G17:G22))} | BF19: {=SUMPRODUCT((E17:E22=BD19)*ISNUMBER(F17:F22)*ISNUMBER(G17:G22)*(F17:F22>G17:G22))+SUMPRODUCT((H17:H22=BD19)*ISNUMBER(F17:F22)*ISNUMBER(G17:G22)*(G17:G22>F17:F22))} | BG19: {=SUMPRODUCT((((E17:E22=BD19)+(H17:H22=BD19))>0)*ISNUMBER(F17:F22)*ISNUMBER(G17:G22)*(F17:F22=G17:G22))} | BH19: =BE19-BF19-BG19 | BI19: {=SUMPRODUCT((E17:E22=BD19)*IFERROR(F17:F22,0))+SUMPRODUCT((H17:H22=BD19)*IFERROR(G17:G22,0))} | BJ19: {=SUMPRODUCT((E17:E22=BD19)*IFERROR(G17:G22,0))+SUMPRODUCT((H17:H22=BD19)*IFERROR(F17:F22,0))} | BK19: =BF19*3+BG19 | BL19: =1+SUMPRODUCT(((BK$18:BK$21>BK19)+(BK$18:BK$21=BK19)*(BM$18:BM$21>BM19)+(BK$18:BK$21=BK19)*(BM$18:BM$21=BM19)*(BN$18:BN$21>BN19)+(BK$18:BK$21=BK19)*(BM$18:BM$21=BM19)*(BN$18:BN$21=BN19)*(BO$18:BO$21>BO19)+(BK$18:BK$21=BK19)*(BM$18:BM$21=BM19)*(BN$18:BN$21=BN19)*(BO$18:BO$21=BO19)*((BI$18:BI$21-BJ$18:BJ$21)>(BI19-BJ19))+(BK$18:BK$21=BK19)*(BM$18:BM$21=BM19)*(BN$18:BN$21=BN19)*(BO$18:BO$21=BO19)*((BI$18:BI$21-BJ$18:BJ$21)=(BI19-BJ19))*(BI$18:BI$21>BI19)+(BK$18:BK$21=BK19)*(BM$18:BM$21=BM19)*(BN$18:BN$21=BN19)*(BO$18:BO$21=BO19)*((BI$18:BI$21-BJ$18:BJ$21)=(BI19-BJ19))*(BI$18:BI$21=BI19)*(ROW(BK$18:BK$21)<ROW(BK19)))*1) | BM19: {=SUMPRODUCT((E$17:E$22=BD19)*ISNUMBER(F$17:F$22)*ISNUMBER(G$17:G$22)*COUNTIFS(BD$18:BD$21,H$17:H$22,BK$18:BK$21,BK19)*((F$17:F$22>G$17:G$22)*3+(F$17:F$22=G$17:G$22)))+SUMPRODUCT((H$17:H$22=BD19)*ISNUMBER(F$17:F$22)*ISNUMBER(G$17:G$22)*COUNTIFS(BD$18:BD$21,E$17:E$22,BK$18:BK$21,BK19)*((G$17:G$22>F$17:F$22)*3+(F$17:F$22=G$17:G$22)))} | BN19: {=SUMPRODUCT((E$17:E$22=BD19)*ISNUMBER(F$17:F$22)*ISNUMBER(G$17:G$22)*COUNTIFS(BD$18:BD$21,H$17:H$22,BK$18:BK$21,BK19)*(F$17:F$22-G$17:G$22))+SUMPRODUCT((H$17:H$22=BD19)*ISNUMBER(F$17:F$22)*ISNUMBER(G$17:G$22)*COUNTIFS(BD$18:BD$21,E$17:E$22,BK$18:BK$21,BK19)*(G$17:G$22-F$17:F$22))} | BO19: {=SUMPRODUCT((E$17:E$22=BD19)*ISNUMBER(F$17:F$22)*ISNUMBER(G$17:G$22)*COUNTIFS(BD$18:BD$21,H$17:H$22,BK$18:BK$21,BK19)*F$17:F$22)+SUMPRODUCT((H$17:H$22=BD19)*ISNUMBER(F$17:F$22)*ISNUMBER(G$17:G$22)*COUNTIFS(BD$18:BD$21,E$17:E$22,BK$18:BK$21,BK19)*G$17:G$22)}
A20: 16 | B20: =TEXT((46192)+(18+4+GmtOffset)/24,"ddd") | C20: =TEXT((46192)+(18+4+GmtOffset)/24,"mmm d, yyyy") | D20: =TEXT((46192)+(18+4+GmtOffset)/24,"h:mm") | E20: Scotland | H20: Morocco | I20: C | K20: =INDEX(BD18:BD21,MATCH(2,BL18:BL21,0)) | L20: =INDEX(BE18:BE21,MATCH(2,BL18:BL21,0)) | M20: =INDEX(BF18:BF21,MATCH(2,BL18:BL21,0)) | N20: =INDEX(BG18:BG21,MATCH(2,BL18:BL21,0)) | O20: =INDEX(BH18:BH21,MATCH(2,BL18:BL21,0)) | P20: =INDEX(BI18:BI21,MATCH(2,BL18:BL21,0))&" - "&INDEX(BJ18:BJ21,MATCH(2,BL18:BL21,0)) | Q20: =INDEX(BK18:BK21,MATCH(2,BL18:BL21,0)) | AE20: =IF(AND(ISNUMBER(AB27),ISNUMBER(AB28)),IF(AB27>AB28,AA27,IF(AB28>AB27,AA28,IF(NOT(AND(ISNUMBER(AC27),ISNUMBER(AC28))),"",IF(AC27>AC28,AA27,IF(AC28>AC27,AA28,IF(NOT(AND(ISNUMBER(AD27),ISNUMBER(AD28))),"",IF(AD27>AD28,AA27,IF(AD28>AD27,AA28,"")))))))),"W98") | BD20: Haiti | BE20: {=SUMPRODUCT((((E17:E22=BD20)+(H17:H22=BD20))>0)*ISNUMBER(F17:F22)*ISNUMBER(G17:G22))} | BF20: {=SUMPRODUCT((E17:E22=BD20)*ISNUMBER(F17:F22)*ISNUMBER(G17:G22)*(F17:F22>G17:G22))+SUMPRODUCT((H17:H22=BD20)*ISNUMBER(F17:F22)*ISNUMBER(G17:G22)*(G17:G22>F17:F22))} | BG20: {=SUMPRODUCT((((E17:E22=BD20)+(H17:H22=BD20))>0)*ISNUMBER(F17:F22)*ISNUMBER(G17:G22)*(F17:F22=G17:G22))} | BH20: =BE20-BF20-BG20 | BI20: {=SUMPRODUCT((E17:E22=BD20)*IFERROR(F17:F22,0))+SUMPRODUCT((H17:H22=BD20)*IFERROR(G17:G22,0))} | BJ20: {=SUMPRODUCT((E17:E22=BD20)*IFERROR(G17:G22,0))+SUMPRODUCT((H17:H22=BD20)*IFERROR(F17:F22,0))} | BK20: =BF20*3+BG20 | BL20: =1+SUMPRODUCT(((BK$18:BK$21>BK20)+(BK$18:BK$21=BK20)*(BM$18:BM$21>BM20)+(BK$18:BK$21=BK20)*(BM$18:BM$21=BM20)*(BN$18:BN$21>BN20)+(BK$18:BK$21=BK20)*(BM$18:BM$21=BM20)*(BN$18:BN$21=BN20)*(BO$18:BO$21>BO20)+(BK$18:BK$21=BK20)*(BM$18:BM$21=BM20)*(BN$18:BN$21=BN20)*(BO$18:BO$21=BO20)*((BI$18:BI$21-BJ$18:BJ$21)>(BI20-BJ20))+(BK$18:BK$21=BK20)*(BM$18:BM$21=BM20)*(BN$18:BN$21=BN20)*(BO$18:BO$21=BO20)*((BI$18:BI$21-BJ$18:BJ$21)=(BI20-BJ20))*(BI$18:BI$21>BI20)+(BK$18:BK$21=BK20)*(BM$18:BM$21=BM20)*(BN$18:BN$21=BN20)*(BO$18:BO$21=BO20)*((BI$18:BI$21-BJ$18:BJ$21)=(BI20-BJ20))*(BI$18:BI$21=BI20)*(ROW(BK$18:BK$21)<ROW(BK20)))*1) | BM20: {=SUMPRODUCT((E$17:E$22=BD20)*ISNUMBER(F$17:F$22)*ISNUMBER(G$17:G$22)*COUNTIFS(BD$18:BD$21,H$17:H$22,BK$18:BK$21,BK20)*((F$17:F$22>G$17:G$22)*3+(F$17:F$22=G$17:G$22)))+SUMPRODUCT((H$17:H$22=BD20)*ISNUMBER(F$17:F$22)*ISNUMBER(G$17:G$22)*COUNTIFS(BD$18:BD$21,E$17:E$22,BK$18:BK$21,BK20)*((G$17:G$22>F$17:F$22)*3+(F$17:F$22=G$17:G$22)))} | BN20: {=SUMPRODUCT((E$17:E$22=BD20)*ISNUMBER(F$17:F$22)*ISNUMBER(G$17:G$22)*COUNTIFS(BD$18:BD$21,H$17:H$22,BK$18:BK$21,BK20)*(F$17:F$22-G$17:G$22))+SUMPRODUCT((H$17:H$22=BD20)*ISNUMBER(F$17:F$22)*ISNUMBER(G$17:G$22)*COUNTIFS(BD$18:BD$21,E$17:E$22,BK$18:BK$21,BK20)*(G$17:G$22-F$17:F$22))} | BO20: {=SUMPRODUCT((E$17:E$22=BD20)*ISNUMBER(F$17:F$22)*ISNUMBER(G$17:G$22)*COUNTIFS(BD$18:BD$21,H$17:H$22,BK$18:BK$21,BK20)*F$17:F$22)+SUMPRODUCT((H$17:H$22=BD20)*ISNUMBER(F$17:F$22)*ISNUMBER(G$17:G$22)*COUNTIFS(BD$18:BD$21,E$17:E$22,BK$18:BK$21,BK20)*G$17:G$22)}
A21: 17 | B21: =TEXT((46197)+(18+4+GmtOffset)/24,"ddd") | C21: =TEXT((46197)+(18+4+GmtOffset)/24,"mmm d, yyyy") | D21: =TEXT((46197)+(18+4+GmtOffset)/24,"h:mm") | E21: Scotland | H21: Brazil | I21: C | K21: =INDEX(BD18:BD21,MATCH(3,BL18:BL21,0)) | L21: =INDEX(BE18:BE21,MATCH(3,BL18:BL21,0)) | M21: =INDEX(BF18:BF21,MATCH(3,BL18:BL21,0)) | N21: =INDEX(BG18:BG21,MATCH(3,BL18:BL21,0)) | O21: =INDEX(BH18:BH21,MATCH(3,BL18:BL21,0)) | P21: =INDEX(BI18:BI21,MATCH(3,BL18:BL21,0))&" - "&INDEX(BJ18:BJ21,MATCH(3,BL18:BL21,0)) | Q21: =INDEX(BK18:BK21,MATCH(3,BL18:BL21,0)) | S21: =IF((COUNTIF($F$5:$G$76,">=0")=144),IFERROR(INDEX($AO$81:$AO$92,9),"Winner I"),"Winner I") | BD21: Scotland | BE21: {=SUMPRODUCT((((E17:E22=BD21)+(H17:H22=BD21))>0)*ISNUMBER(F17:F22)*ISNUMBER(G17:G22))} | BF21: {=SUMPRODUCT((E17:E22=BD21)*ISNUMBER(F17:F22)*ISNUMBER(G17:G22)*(F17:F22>G17:G22))+SUMPRODUCT((H17:H22=BD21)*ISNUMBER(F17:F22)*ISNUMBER(G17:G22)*(G17:G22>F17:F22))} | BG21: {=SUMPRODUCT((((E17:E22=BD21)+(H17:H22=BD21))>0)*ISNUMBER(F17:F22)*ISNUMBER(G17:G22)*(F17:F22=G17:G22))} | BH21: =BE21-BF21-BG21 | BI21: {=SUMPRODUCT((E17:E22=BD21)*IFERROR(F17:F22,0))+SUMPRODUCT((H17:H22=BD21)*IFERROR(G17:G22,0))} | BJ21: {=SUMPRODUCT((E17:E22=BD21)*IFERROR(G17:G22,0))+SUMPRODUCT((H17:H22=BD21)*IFERROR(F17:F22,0))} | BK21: =BF21*3+BG21 | BL21: =1+SUMPRODUCT(((BK$18:BK$21>BK21)+(BK$18:BK$21=BK21)*(BM$18:BM$21>BM21)+(BK$18:BK$21=BK21)*(BM$18:BM$21=BM21)*(BN$18:BN$21>BN21)+(BK$18:BK$21=BK21)*(BM$18:BM$21=BM21)*(BN$18:BN$21=BN21)*(BO$18:BO$21>BO21)+(BK$18:BK$21=BK21)*(BM$18:BM$21=BM21)*(BN$18:BN$21=BN21)*(BO$18:BO$21=BO21)*((BI$18:BI$21-BJ$18:BJ$21)>(BI21-BJ21))+(BK$18:BK$21=BK21)*(BM$18:BM$21=BM21)*(BN$18:BN$21=BN21)*(BO$18:BO$21=BO21)*((BI$18:BI$21-BJ$18:BJ$21)=(BI21-BJ21))*(BI$18:BI$21>BI21)+(BK$18:BK$21=BK21)*(BM$18:BM$21=BM21)*(BN$18:BN$21=BN21)*(BO$18:BO$21=BO21)*((BI$18:BI$21-BJ$18:BJ$21)=(BI21-BJ21))*(BI$18:BI$21=BI21)*(ROW(BK$18:BK$21)<ROW(BK21)))*1) | BM21: {=SUMPRODUCT((E$17:E$22=BD21)*ISNUMBER(F$17:F$22)*ISNUMBER(G$17:G$22)*COUNTIFS(BD$18:BD$21,H$17:H$22,BK$18:BK$21,BK21)*((F$17:F$22>G$17:G$22)*3+(F$17:F$22=G$17:G$22)))+SUMPRODUCT((H$17:H$22=BD21)*ISNUMBER(F$17:F$22)*ISNUMBER(G$17:G$22)*COUNTIFS(BD$18:BD$21,E$17:E$22,BK$18:BK$21,BK21)*((G$17:G$22>F$17:F$22)*3+(F$17:F$22=G$17:G$22)))} | BN21: {=SUMPRODUCT((E$17:E$22=BD21)*ISNUMBER(F$17:F$22)*ISNUMBER(G$17:G$22)*COUNTIFS(BD$18:BD$21,H$17:H$22,BK$18:BK$21,BK21)*(F$17:F$22-G$17:G$22))+SUMPRODUCT((H$17:H$22=BD21)*ISNUMBER(F$17:F$22)*ISNUMBER(G$17:G$22)*COUNTIFS(BD$18:BD$21,E$17:E$22,BK$18:BK$21,BK21)*(G$17:G$22-F$17:F$22))} | BO21: {=SUMPRODUCT((E$17:E$22=BD21)*ISNUMBER(F$17:F$22)*ISNUMBER(G$17:G$22)*COUNTIFS(BD$18:BD$21,H$17:H$22,BK$18:BK$21,BK21)*F$17:F$22)+SUMPRODUCT((H$17:H$22=BD21)*ISNUMBER(F$17:F$22)*ISNUMBER(G$17:G$22)*COUNTIFS(BD$18:BD$21,E$17:E$22,BK$18:BK$21,BK21)*G$17:G$22)}
A22: 18 | B22: =TEXT((46197)+(18+4+GmtOffset)/24,"ddd") | C22: =TEXT((46197)+(18+4+GmtOffset)/24,"mmm d, yyyy") | D22: =TEXT((46197)+(18+4+GmtOffset)/24,"h:mm") | E22: Morocco | H22: Haiti | I22: C | K22: =INDEX(BD18:BD21,MATCH(4,BL18:BL21,0)) | L22: =INDEX(BE18:BE21,MATCH(4,BL18:BL21,0)) | M22: =INDEX(BF18:BF21,MATCH(4,BL18:BL21,0)) | N22: =INDEX(BG18:BG21,MATCH(4,BL18:BL21,0)) | O22: =INDEX(BH18:BH21,MATCH(4,BL18:BL21,0)) | P22: =INDEX(BI18:BI21,MATCH(4,BL18:BL21,0))&" - "&INDEX(BJ18:BJ21,MATCH(4,BL18:BL21,0)) | Q22: =INDEX(BK18:BK21,MATCH(4,BL18:BL21,0)) | S22: =IF((COUNTIF($F$5:$G$76,">=0")=144),IFERROR(INDEX($AQ$81:$AQ$92,MATCH($BN$81,$AN$81:$AN$92,0)),"Best 3rd C/D/F/G/H"),"Best 3rd C/D/F/G/H")
A23: 19 | B23: =TEXT((46185)+(21+4+GmtOffset)/24,"ddd") | C23: =TEXT((46185)+(21+4+GmtOffset)/24,"mmm d, yyyy") | D23: =TEXT((46185)+(21+4+GmtOffset)/24,"h:mm") | E23: United States | F23: 4 | G23: 1 | H23: Paraguay | I23: D | K23: Group D | W23: =IF(AND(ISNUMBER(T17),ISNUMBER(T18)),IF(T17>T18,S17,IF(T18>T17,S18,IF(NOT(AND(ISNUMBER(U17),ISNUMBER(U18))),"",IF(U17>U18,S17,IF(U18>U17,S18,IF(NOT(AND(ISNUMBER(V17),ISNUMBER(V18))),"",IF(V17>V18,S17,IF(V18>V17,S18,"")))))))),"W76")
A24: 20 | B24: =TEXT((46187)+(0+4+GmtOffset)/24,"ddd") | C24: =TEXT((46187)+(0+4+GmtOffset)/24,"mmm d, yyyy") | D24: =TEXT((46187)+(0+4+GmtOffset)/24,"h:mm") | E24: Australia | H24: Türkiye | I24: D | L24: PL | M24: W | N24: D | O24: L | P24: GF - GA | Q24: P | W24: =IF(AND(ISNUMBER(T25),ISNUMBER(T26)),IF(T25>T26,S25,IF(T26>T25,S26,IF(NOT(AND(ISNUMBER(U25),ISNUMBER(U26))),"",IF(U25>U26,S25,IF(U26>U25,S26,IF(NOT(AND(ISNUMBER(V25),ISNUMBER(V26))),"",IF(V25>V26,S25,IF(V26>V25,S26,"")))))))),"W78") | BD24: United States | BE24: {=SUMPRODUCT((((E23:E28=BD24)+(H23:H28=BD24))>0)*ISNUMBER(F23:F28)*ISNUMBER(G23:G28))} | BF24: {=SUMPRODUCT((E23:E28=BD24)*ISNUMBER(F23:F28)*ISNUMBER(G23:G28)*(F23:F28>G23:G28))+SUMPRODUCT((H23:H28=BD24)*ISNUMBER(F23:F28)*ISNUMBER(G23:G28)*(G23:G28>F23:F28))} | BG24: {=SUMPRODUCT((((E23:E28=BD24)+(H23:H28=BD24))>0)*ISNUMBER(F23:F28)*ISNUMBER(G23:G28)*(F23:F28=G23:G28))} | BH24: =BE24-BF24-BG24 | BI24: {=SUMPRODUCT((E23:E28=BD24)*IFERROR(F23:F28,0))+SUMPRODUCT((H23:H28=BD24)*IFERROR(G23:G28,0))} | BJ24: {=SUMPRODUCT((E23:E28=BD24)*IFERROR(G23:G28,0))+SUMPRODUCT((H23:H28=BD24)*IFERROR(F23:F28,0))} | BK24: =BF24*3+BG24 | BL24: =1+SUMPRODUCT(((BK$24:BK$27>BK24)+(BK$24:BK$27=BK24)*(BM$24:BM$27>BM24)+(BK$24:BK$27=BK24)*(BM$24:BM$27=BM24)*(BN$24:BN$27>BN24)+(BK$24:BK$27=BK24)*(BM$24:BM$27=BM24)*(BN$24:BN$27=BN24)*(BO$24:BO$27>BO24)+(BK$24:BK$27=BK24)*(BM$24:BM$27=BM24)*(BN$24:BN$27=BN24)*(BO$24:BO$27=BO24)*((BI$24:BI$27-BJ$24:BJ$27)>(BI24-BJ24))+(BK$24:BK$27=BK24)*(BM$24:BM$27=BM24)*(BN$24:BN$27=BN24)*(BO$24:BO$27=BO24)*((BI$24:BI$27-BJ$24:BJ$27)=(BI24-BJ24))*(BI$24:BI$27>BI24)+(BK$24:BK$27=BK24)*(BM$24:BM$27=BM24)*(BN$24:BN$27=BN24)*(BO$24:BO$27=BO24)*((BI$24:BI$27-BJ$24:BJ$27)=(BI24-BJ24))*(BI$24:BI$27=BI24)*(ROW(BK$24:BK$27)<ROW(BK24)))*1) | BM24: {=SUMPRODUCT((E$23:E$28=BD24)*ISNUMBER(F$23:F$28)*ISNUMBER(G$23:G$28)*COUNTIFS(BD$24:BD$27,H$23:H$28,BK$24:BK$27,BK24)*((F$23:F$28>G$23:G$28)*3+(F$23:F$28=G$23:G$28)))+SUMPRODUCT((H$23:H$28=BD24)*ISNUMBER(F$23:F$28)*ISNUMBER(G$23:G$28)*COUNTIFS(BD$24:BD$27,E$23:E$28,BK$24:BK$27,BK24)*((G$23:G$28>F$23:F$28)*3+(F$23:F$28=G$23:G$28)))} | BN24: {=SUMPRODUCT((E$23:E$28=BD24)*ISNUMBER(F$23:F$28)*ISNUMBER(G$23:G$28)*COUNTIFS(BD$24:BD$27,H$23:H$28,BK$24:BK$27,BK24)*(F$23:F$28-G$23:G$28))+SUMPRODUCT((H$23:H$28=BD24)*ISNUMBER(F$23:F$28)*ISNUMBER(G$23:G$28)*COUNTIFS(BD$24:BD$27,E$23:E$28,BK$24:BK$27,BK24)*(G$23:G$28-F$23:F$28))} | BO24: {=SUMPRODUCT((E$23:E$28=BD24)*ISNUMBER(F$23:F$28)*ISNUMBER(G$23:G$28)*COUNTIFS(BD$24:BD$27,H$23:H$28,BK$24:BK$27,BK24)*F$23:F$28)+SUMPRODUCT((H$23:H$28=BD24)*ISNUMBER(F$23:F$28)*ISNUMBER(G$23:G$28)*COUNTIFS(BD$24:BD$27,E$23:E$28,BK$24:BK$27,BK24)*G$23:G$28)}
A25: 21 | B25: =TEXT((46192)+(15+4+GmtOffset)/24,"ddd") | C25: =TEXT((46192)+(15+4+GmtOffset)/24,"mmm d, yyyy") | D25: =TEXT((46192)+(15+4+GmtOffset)/24,"h:mm") | E25: United States | H25: Australia | I25: D | K25: =INDEX(BD24:BD27,MATCH(1,BL24:BL27,0)) | L25: =INDEX(BE24:BE27,MATCH(1,BL24:BL27,0)) | M25: =INDEX(BF24:BF27,MATCH(1,BL24:BL27,0)) | N25: =INDEX(BG24:BG27,MATCH(1,BL24:BL27,0)) | O25: =INDEX(BH24:BH27,MATCH(1,BL24:BL27,0)) | P25: =INDEX(BI24:BI27,MATCH(1,BL24:BL27,0))&" - "&INDEX(BJ24:BJ27,MATCH(1,BL24:BL27,0)) | Q25: =INDEX(BK24:BK27,MATCH(1,BL24:BL27,0)) | S25: =IF((COUNTIF($F$5:$G$76,">=0")=144),IFERROR(INDEX($AP$81:$AP$92,5),"Runner-up E"),"Runner-up E") | BD25: Paraguay | BE25: {=SUMPRODUCT((((E23:E28=BD25)+(H23:H28=BD25))>0)*ISNUMBER(F23:F28)*ISNUMBER(G23:G28))} | BF25: {=SUMPRODUCT((E23:E28=BD25)*ISNUMBER(F23:F28)*ISNUMBER(G23:G28)*(F23:F28>G23:G28))+SUMPRODUCT((H23:H28=BD25)*ISNUMBER(F23:F28)*ISNUMBER(G23:G28)*(G23:G28>F23:F28))} | BG25: {=SUMPRODUCT((((E23:E28=BD25)+(H23:H28=BD25))>0)*ISNUMBER(F23:F28)*ISNUMBER(G23:G28)*(F23:F28=G23:G28))} | BH25: =BE25-BF25-BG25 | BI25: {=SUMPRODUCT((E23:E28=BD25)*IFERROR(F23:F28,0))+SUMPRODUCT((H23:H28=BD25)*IFERROR(G23:G28,0))} | BJ25: {=SUMPRODUCT((E23:E28=BD25)*IFERROR(G23:G28,0))+SUMPRODUCT((H23:H28=BD25)*IFERROR(F23:F28,0))} | BK25: =BF25*3+BG25 | BL25: =1+SUMPRODUCT(((BK$24:BK$27>BK25)+(BK$24:BK$27=BK25)*(BM$24:BM$27>BM25)+(BK$24:BK$27=BK25)*(BM$24:BM$27=BM25)*(BN$24:BN$27>BN25)+(BK$24:BK$27=BK25)*(BM$24:BM$27=BM25)*(BN$24:BN$27=BN25)*(BO$24:BO$27>BO25)+(BK$24:BK$27=BK25)*(BM$24:BM$27=BM25)*(BN$24:BN$27=BN25)*(BO$24:BO$27=BO25)*((BI$24:BI$27-BJ$24:BJ$27)>(BI25-BJ25))+(BK$24:BK$27=BK25)*(BM$24:BM$27=BM25)*(BN$24:BN$27=BN25)*(BO$24:BO$27=BO25)*((BI$24:BI$27-BJ$24:BJ$27)=(BI25-BJ25))*(BI$24:BI$27>BI25)+(BK$24:BK$27=BK25)*(BM$24:BM$27=BM25)*(BN$24:BN$27=BN25)*(BO$24:BO$27=BO25)*((BI$24:BI$27-BJ$24:BJ$27)=(BI25-BJ25))*(BI$24:BI$27=BI25)*(ROW(BK$24:BK$27)<ROW(BK25)))*1) | BM25: {=SUMPRODUCT((E$23:E$28=BD25)*ISNUMBER(F$23:F$28)*ISNUMBER(G$23:G$28)*COUNTIFS(BD$24:BD$27,H$23:H$28,BK$24:BK$27,BK25)*((F$23:F$28>G$23:G$28)*3+(F$23:F$28=G$23:G$28)))+SUMPRODUCT((H$23:H$28=BD25)*ISNUMBER(F$23:F$28)*ISNUMBER(G$23:G$28)*COUNTIFS(BD$24:BD$27,E$23:E$28,BK$24:BK$27,BK25)*((G$23:G$28>F$23:F$28)*3+(F$23:F$28=G$23:G$28)))} | BN25: {=SUMPRODUCT((E$23:E$28=BD25)*ISNUMBER(F$23:F$28)*ISNUMBER(G$23:G$28)*COUNTIFS(BD$24:BD$27,H$23:H$28,BK$24:BK$27,BK25)*(F$23:F$28-G$23:G$28))+SUMPRODUCT((H$23:H$28=BD25)*ISNUMBER(F$23:F$28)*ISNUMBER(G$23:G$28)*COUNTIFS(BD$24:BD$27,E$23:E$28,BK$24:BK$27,BK25)*(G$23:G$28-F$23:F$28))} | BO25: {=SUMPRODUCT((E$23:E$28=BD25)*ISNUMBER(F$23:F$28)*ISNUMBER(G$23:G$28)*COUNTIFS(BD$24:BD$27,H$23:H$28,BK$24:BK$27,BK25)*F$23:F$28)+SUMPRODUCT((H$23:H$28=BD25)*ISNUMBER(F$23:F$28)*ISNUMBER(G$23:G$28)*COUNTIFS(BD$24:BD$27,E$23:E$28,BK$24:BK$27,BK25)*G$23:G$28)}
A26: 22 | B26: =TEXT((46192)+(23+4+GmtOffset)/24,"ddd") | C26: =TEXT((46192)+(23+4+GmtOffset)/24,"mmm d, yyyy") | D26: =TEXT((46192)+(23+4+GmtOffset)/24,"h:mm") | E26: Türkiye | H26: Paraguay | I26: D | K26: =INDEX(BD24:BD27,MATCH(2,BL24:BL27,0)) | L26: =INDEX(BE24:BE27,MATCH(2,BL24:BL27,0)) | M26: =INDEX(BF24:BF27,MATCH(2,BL24:BL27,0)) | N26: =INDEX(BG24:BG27,MATCH(2,BL24:BL27,0)) | O26: =INDEX(BH24:BH27,MATCH(2,BL24:BL27,0)) | P26: =INDEX(BI24:BI27,MATCH(2,BL24:BL27,0))&" - "&INDEX(BJ24:BJ27,MATCH(2,BL24:BL27,0)) | Q26: =INDEX(BK24:BK27,MATCH(2,BL24:BL27,0)) | S26: =IF((COUNTIF($F$5:$G$76,">=0")=144),IFERROR(INDEX($AP$81:$AP$92,9),"Runner-up I"),"Runner-up I") | BD26: Australia | BE26: {=SUMPRODUCT((((E23:E28=BD26)+(H23:H28=BD26))>0)*ISNUMBER(F23:F28)*ISNUMBER(G23:G28))} | BF26: {=SUMPRODUCT((E23:E28=BD26)*ISNUMBER(F23:F28)*ISNUMBER(G23:G28)*(F23:F28>G23:G28))+SUMPRODUCT((H23:H28=BD26)*ISNUMBER(F23:F28)*ISNUMBER(G23:G28)*(G23:G28>F23:F28))} | BG26: {=SUMPRODUCT((((E23:E28=BD26)+(H23:H28=BD26))>0)*ISNUMBER(F23:F28)*ISNUMBER(G23:G28)*(F23:F28=G23:G28))} | BH26: =BE26-BF26-BG26 | BI26: {=SUMPRODUCT((E23:E28=BD26)*IFERROR(F23:F28,0))+SUMPRODUCT((H23:H28=BD26)*IFERROR(G23:G28,0))} | BJ26: {=SUMPRODUCT((E23:E28=BD26)*IFERROR(G23:G28,0))+SUMPRODUCT((H23:H28=BD26)*IFERROR(F23:F28,0))} | BK26: =BF26*3+BG26 | BL26: =1+SUMPRODUCT(((BK$24:BK$27>BK26)+(BK$24:BK$27=BK26)*(BM$24:BM$27>BM26)+(BK$24:BK$27=BK26)*(BM$24:BM$27=BM26)*(BN$24:BN$27>BN26)+(BK$24:BK$27=BK26)*(BM$24:BM$27=BM26)*(BN$24:BN$27=BN26)*(BO$24:BO$27>BO26)+(BK$24:BK$27=BK26)*(BM$24:BM$27=BM26)*(BN$24:BN$27=BN26)*(BO$24:BO$27=BO26)*((BI$24:BI$27-BJ$24:BJ$27)>(BI26-BJ26))+(BK$24:BK$27=BK26)*(BM$24:BM$27=BM26)*(BN$24:BN$27=BN26)*(BO$24:BO$27=BO26)*((BI$24:BI$27-BJ$24:BJ$27)=(BI26-BJ26))*(BI$24:BI$27>BI26)+(BK$24:BK$27=BK26)*(BM$24:BM$27=BM26)*(BN$24:BN$27=BN26)*(BO$24:BO$27=BO26)*((BI$24:BI$27-BJ$24:BJ$27)=(BI26-BJ26))*(BI$24:BI$27=BI26)*(ROW(BK$24:BK$27)<ROW(BK26)))*1) | BM26: {=SUMPRODUCT((E$23:E$28=BD26)*ISNUMBER(F$23:F$28)*ISNUMBER(G$23:G$28)*COUNTIFS(BD$24:BD$27,H$23:H$28,BK$24:BK$27,BK26)*((F$23:F$28>G$23:G$28)*3+(F$23:F$28=G$23:G$28)))+SUMPRODUCT((H$23:H$28=BD26)*ISNUMBER(F$23:F$28)*ISNUMBER(G$23:G$28)*COUNTIFS(BD$24:BD$27,E$23:E$28,BK$24:BK$27,BK26)*((G$23:G$28>F$23:F$28)*3+(F$23:F$28=G$23:G$28)))} | BN26: {=SUMPRODUCT((E$23:E$28=BD26)*ISNUMBER(F$23:F$28)*ISNUMBER(G$23:G$28)*COUNTIFS(BD$24:BD$27,H$23:H$28,BK$24:BK$27,BK26)*(F$23:F$28-G$23:G$28))+SUMPRODUCT((H$23:H$28=BD26)*ISNUMBER(F$23:F$28)*ISNUMBER(G$23:G$28)*COUNTIFS(BD$24:BD$27,E$23:E$28,BK$24:BK$27,BK26)*(G$23:G$28-F$23:F$28))} | BO26: {=SUMPRODUCT((E$23:E$28=BD26)*ISNUMBER(F$23:F$28)*ISNUMBER(G$23:G$28)*COUNTIFS(BD$24:BD$27,H$23:H$28,BK$24:BK$27,BK26)*F$23:F$28)+SUMPRODUCT((H$23:H$28=BD26)*ISNUMBER(F$23:F$28)*ISNUMBER(G$23:G$28)*COUNTIFS(BD$24:BD$27,E$23:E$28,BK$24:BK$27,BK26)*G$23:G$28)}
A27: 23 | B27: =TEXT((46198)+(22+4+GmtOffset)/24,"ddd") | C27: =TEXT((46198)+(22+4+GmtOffset)/24,"mmm d, yyyy") | D27: =TEXT((46198)+(22+4+GmtOffset)/24,"h:mm") | E27: Türkiye | H27: United States | I27: D | K27: =INDEX(BD24:BD27,MATCH(3,BL24:BL27,0)) | L27: =INDEX(BE24:BE27,MATCH(3,BL24:BL27,0)) | M27: =INDEX(BF24:BF27,MATCH(3,BL24:BL27,0)) | N27: =INDEX(BG24:BG27,MATCH(3,BL24:BL27,0)) | O27: =INDEX(BH24:BH27,MATCH(3,BL24:BL27,0)) | P27: =INDEX(BI24:BI27,MATCH(3,BL24:BL27,0))&" - "&INDEX(BJ24:BJ27,MATCH(3,BL24:BL27,0)) | Q27: =INDEX(BK24:BK27,MATCH(3,BL24:BL27,0)) | AA27: =IF(AND(ISNUMBER(X39),ISNUMBER(X40)),IF(X39>X40,W39,IF(X40>X39,W40,IF(NOT(AND(ISNUMBER(Y39),ISNUMBER(Y40))),"",IF(Y39>Y40,W39,IF(Y40>Y39,W40,IF(NOT(AND(ISNUMBER(Z39),ISNUMBER(Z40))),"",IF(Z39>Z40,W39,IF(Z40>Z39,W40,"")))))))),"W93") | BD27: Türkiye | BE27: {=SUMPRODUCT((((E23:E28=BD27)+(H23:H28=BD27))>0)*ISNUMBER(F23:F28)*ISNUMBER(G23:G28))} | BF27: {=SUMPRODUCT((E23:E28=BD27)*ISNUMBER(F23:F28)*ISNUMBER(G23:G28)*(F23:F28>G23:G28))+SUMPRODUCT((H23:H28=BD27)*ISNUMBER(F23:F28)*ISNUMBER(G23:G28)*(G23:G28>F23:F28))} | BG27: {=SUMPRODUCT((((E23:E28=BD27)+(H23:H28=BD27))>0)*ISNUMBER(F23:F28)*ISNUMBER(G23:G28)*(F23:F28=G23:G28))} | BH27: =BE27-BF27-BG27 | BI27: {=SUMPRODUCT((E23:E28=BD27)*IFERROR(F23:F28,0))+SUMPRODUCT((H23:H28=BD27)*IFERROR(G23:G28,0))} | BJ27: {=SUMPRODUCT((E23:E28=BD27)*IFERROR(G23:G28,0))+SUMPRODUCT((H23:H28=BD27)*IFERROR(F23:F28,0))} | BK27: =BF27*3+BG27 | BL27: =1+SUMPRODUCT(((BK$24:BK$27>BK27)+(BK$24:BK$27=BK27)*(BM$24:BM$27>BM27)+(BK$24:BK$27=BK27)*(BM$24:BM$27=BM27)*(BN$24:BN$27>BN27)+(BK$24:BK$27=BK27)*(BM$24:BM$27=BM27)*(BN$24:BN$27=BN27)*(BO$24:BO$27>BO27)+(BK$24:BK$27=BK27)*(BM$24:BM$27=BM27)*(BN$24:BN$27=BN27)*(BO$24:BO$27=BO27)*((BI$24:BI$27-BJ$24:BJ$27)>(BI27-BJ27))+(BK$24:BK$27=BK27)*(BM$24:BM$27=BM27)*(BN$24:BN$27=BN27)*(BO$24:BO$27=BO27)*((BI$24:BI$27-BJ$24:BJ$27)=(BI27-BJ27))*(BI$24:BI$27>BI27)+(BK$24:BK$27=BK27)*(BM$24:BM$27=BM27)*(BN$24:BN$27=BN27)*(BO$24:BO$27=BO27)*((BI$24:BI$27-BJ$24:BJ$27)=(BI27-BJ27))*(BI$24:BI$27=BI27)*(ROW(BK$24:BK$27)<ROW(BK27)))*1) | BM27: {=SUMPRODUCT((E$23:E$28=BD27)*ISNUMBER(F$23:F$28)*ISNUMBER(G$23:G$28)*COUNTIFS(BD$24:BD$27,H$23:H$28,BK$24:BK$27,BK27)*((F$23:F$28>G$23:G$28)*3+(F$23:F$28=G$23:G$28)))+SUMPRODUCT((H$23:H$28=BD27)*ISNUMBER(F$23:F$28)*ISNUMBER(G$23:G$28)*COUNTIFS(BD$24:BD$27,E$23:E$28,BK$24:BK$27,BK27)*((G$23:G$28>F$23:F$28)*3+(F$23:F$28=G$23:G$28)))} | BN27: {=SUMPRODUCT((E$23:E$28=BD27)*ISNUMBER(F$23:F$28)*ISNUMBER(G$23:G$28)*COUNTIFS(BD$24:BD$27,H$23:H$28,BK$24:BK$27,BK27)*(F$23:F$28-G$23:G$28))+SUMPRODUCT((H$23:H$28=BD27)*ISNUMBER(F$23:F$28)*ISNUMBER(G$23:G$28)*COUNTIFS(BD$24:BD$27,E$23:E$28,BK$24:BK$27,BK27)*(G$23:G$28-F$23:F$28))} | BO27: {=SUMPRODUCT((E$23:E$28=BD27)*ISNUMBER(F$23:F$28)*ISNUMBER(G$23:G$28)*COUNTIFS(BD$24:BD$27,H$23:H$28,BK$24:BK$27,BK27)*F$23:F$28)+SUMPRODUCT((H$23:H$28=BD27)*ISNUMBER(F$23:F$28)*ISNUMBER(G$23:G$28)*COUNTIFS(BD$24:BD$27,E$23:E$28,BK$24:BK$27,BK27)*G$23:G$28)}
A28: 24 | B28: =TEXT((46198)+(22+4+GmtOffset)/24,"ddd") | C28: =TEXT((46198)+(22+4+GmtOffset)/24,"mmm d, yyyy") | D28: =TEXT((46198)+(22+4+GmtOffset)/24,"h:mm") | E28: Paraguay | H28: Australia | I28: D | K28: =INDEX(BD24:BD27,MATCH(4,BL24:BL27,0)) | L28: =INDEX(BE24:BE27,MATCH(4,BL24:BL27,0)) | M28: =INDEX(BF24:BF27,MATCH(4,BL24:BL27,0)) | N28: =INDEX(BG24:BG27,MATCH(4,BL24:BL27,0)) | O28: =INDEX(BH24:BH27,MATCH(4,BL24:BL27,0)) | P28: =INDEX(BI24:BI27,MATCH(4,BL24:BL27,0))&" - "&INDEX(BJ24:BJ27,MATCH(4,BL24:BL27,0)) | Q28: =INDEX(BK24:BK27,MATCH(4,BL24:BL27,0)) | AA28: =IF(AND(ISNUMBER(X47),ISNUMBER(X48)),IF(X47>X48,W47,IF(X48>X47,W48,IF(NOT(AND(ISNUMBER(Y47),ISNUMBER(Y48))),"",IF(Y47>Y48,W47,IF(Y48>Y47,W48,IF(NOT(AND(ISNUMBER(Z47),ISNUMBER(Z48))),"",IF(Z47>Z48,W47,IF(Z48>Z47,W48,"")))))))),"W94")
A29: 25 | B29: =TEXT((46187)+(13+4+GmtOffset)/24,"ddd") | C29: =TEXT((46187)+(13+4+GmtOffset)/24,"mmm d, yyyy") | D29: =TEXT((46187)+(13+4+GmtOffset)/24,"h:mm") | E29: Germany | H29: Curaçao | I29: E | K29: Group E | S29: =IF((COUNTIF($F$5:$G$76,">=0")=144),IFERROR(INDEX($AO$81:$AO$92,1),"Winner A"),"Winner A")
A30: 26 | B30: =TEXT((46187)+(19+4+GmtOffset)/24,"ddd") | C30: =TEXT((46187)+(19+4+GmtOffset)/24,"mmm d, yyyy") | D30: =TEXT((46187)+(19+4+GmtOffset)/24,"h:mm") | E30: Ivory Coast | H30: Ecuador | I30: E | L30: PL | M30: W | N30: D | O30: L | P30: GF - GA | Q30: P | S30: =IF((COUNTIF($F$5:$G$76,">=0")=144),IFERROR(INDEX($AQ$81:$AQ$92,MATCH($BO$81,$AN$81:$AN$92,0)),"Best 3rd C/E/F/H/I"),"Best 3rd C/E/F/H/I") | BD30: Germany | BE30: {=SUMPRODUCT((((E29:E34=BD30)+(H29:H34=BD30))>0)*ISNUMBER(F29:F34)*ISNUMBER(G29:G34))} | BF30: {=SUMPRODUCT((E29:E34=BD30)*ISNUMBER(F29:F34)*ISNUMBER(G29:G34)*(F29:F34>G29:G34))+SUMPRODUCT((H29:H34=BD30)*ISNUMBER(F29:F34)*ISNUMBER(G29:G34)*(G29:G34>F29:F34))} | BG30: {=SUMPRODUCT((((E29:E34=BD30)+(H29:H34=BD30))>0)*ISNUMBER(F29:F34)*ISNUMBER(G29:G34)*(F29:F34=G29:G34))} | BH30: =BE30-BF30-BG30 | BI30: {=SUMPRODUCT((E29:E34=BD30)*IFERROR(F29:F34,0))+SUMPRODUCT((H29:H34=BD30)*IFERROR(G29:G34,0))} | BJ30: {=SUMPRODUCT((E29:E34=BD30)*IFERROR(G29:G34,0))+SUMPRODUCT((H29:H34=BD30)*IFERROR(F29:F34,0))} | BK30: =BF30*3+BG30 | BL30: =1+SUMPRODUCT(((BK$30:BK$33>BK30)+(BK$30:BK$33=BK30)*(BM$30:BM$33>BM30)+(BK$30:BK$33=BK30)*(BM$30:BM$33=BM30)*(BN$30:BN$33>BN30)+(BK$30:BK$33=BK30)*(BM$30:BM$33=BM30)*(BN$30:BN$33=BN30)*(BO$30:BO$33>BO30)+(BK$30:BK$33=BK30)*(BM$30:BM$33=BM30)*(BN$30:BN$33=BN30)*(BO$30:BO$33=BO30)*((BI$30:BI$33-BJ$30:BJ$33)>(BI30-BJ30))+(BK$30:BK$33=BK30)*(BM$30:BM$33=BM30)*(BN$30:BN$33=BN30)*(BO$30:BO$33=BO30)*((BI$30:BI$33-BJ$30:BJ$33)=(BI30-BJ30))*(BI$30:BI$33>BI30)+(BK$30:BK$33=BK30)*(BM$30:BM$33=BM30)*(BN$30:BN$33=BN30)*(BO$30:BO$33=BO30)*((BI$30:BI$33-BJ$30:BJ$33)=(BI30-BJ30))*(BI$30:BI$33=BI30)*(ROW(BK$30:BK$33)<ROW(BK30)))*1) | BM30: {=SUMPRODUCT((E$29:E$34=BD30)*ISNUMBER(F$29:F$34)*ISNUMBER(G$29:G$34)*COUNTIFS(BD$30:BD$33,H$29:H$34,BK$30:BK$33,BK30)*((F$29:F$34>G$29:G$34)*3+(F$29:F$34=G$29:G$34)))+SUMPRODUCT((H$29:H$34=BD30)*ISNUMBER(F$29:F$34)*ISNUMBER(G$29:G$34)*COUNTIFS(BD$30:BD$33,E$29:E$34,BK$30:BK$33,BK30)*((G$29:G$34>F$29:F$34)*3+(F$29:F$34=G$29:G$34)))} | BN30: {=SUMPRODUCT((E$29:E$34=BD30)*ISNUMBER(F$29:F$34)*ISNUMBER(G$29:G$34)*COUNTIFS(BD$30:BD$33,H$29:H$34,BK$30:BK$33,BK30)*(F$29:F$34-G$29:G$34))+SUMPRODUCT((H$29:H$34=BD30)*ISNUMBER(F$29:F$34)*ISNUMBER(G$29:G$34)*COUNTIFS(BD$30:BD$33,E$29:E$34,BK$30:BK$33,BK30)*(G$29:G$34-F$29:F$34))} | BO30: {=SUMPRODUCT((E$29:E$34=BD30)*ISNUMBER(F$29:F$34)*ISNUMBER(G$29:G$34)*COUNTIFS(BD$30:BD$33,H$29:H$34,BK$30:BK$33,BK30)*F$29:F$34)+SUMPRODUCT((H$29:H$34=BD30)*ISNUMBER(F$29:F$34)*ISNUMBER(G$29:G$34)*COUNTIFS(BD$30:BD$33,E$29:E$34,BK$30:BK$33,BK30)*G$29:G$34)}
A31: 27 | B31: =TEXT((46193)+(16+4+GmtOffset)/24,"ddd") | C31: =TEXT((46193)+(16+4+GmtOffset)/24,"mmm d, yyyy") | D31: =TEXT((46193)+(16+4+GmtOffset)/24,"h:mm") | E31: Germany | H31: Ivory Coast | I31: E | K31: =INDEX(BD30:BD33,MATCH(1,BL30:BL33,0)) | L31: =INDEX(BE30:BE33,MATCH(1,BL30:BL33,0)) | M31: =INDEX(BF30:BF33,MATCH(1,BL30:BL33,0)) | N31: =INDEX(BG30:BG33,MATCH(1,BL30:BL33,0)) | O31: =INDEX(BH30:BH33,MATCH(1,BL30:BL33,0)) | P31: =INDEX(BI30:BI33,MATCH(1,BL30:BL33,0))&" - "&INDEX(BJ30:BJ33,MATCH(1,BL30:BL33,0)) | Q31: =INDEX(BK30:BK33,MATCH(1,BL30:BL33,0)) | W31: =IF(AND(ISNUMBER(T29),ISNUMBER(T30)),IF(T29>T30,S29,IF(T30>T29,S30,IF(NOT(AND(ISNUMBER(U29),ISNUMBER(U30))),"",IF(U29>U30,S29,IF(U30>U29,S30,IF(NOT(AND(ISNUMBER(V29),ISNUMBER(V30))),"",IF(V29>V30,S29,IF(V30>V29,S30,"")))))))),"W79") | BD31: Curaçao | BE31: {=SUMPRODUCT((((E29:E34=BD31)+(H29:H34=BD31))>0)*ISNUMBER(F29:F34)*ISNUMBER(G29:G34))} | BF31: {=SUMPRODUCT((E29:E34=BD31)*ISNUMBER(F29:F34)*ISNUMBER(G29:G34)*(F29:F34>G29:G34))+SUMPRODUCT((H29:H34=BD31)*ISNUMBER(F29:F34)*ISNUMBER(G29:G34)*(G29:G34>F29:F34))} | BG31: {=SUMPRODUCT((((E29:E34=BD31)+(H29:H34=BD31))>0)*ISNUMBER(F29:F34)*ISNUMBER(G29:G34)*(F29:F34=G29:G34))} | BH31: =BE31-BF31-BG31 | BI31: {=SUMPRODUCT((E29:E34=BD31)*IFERROR(F29:F34,0))+SUMPRODUCT((H29:H34=BD31)*IFERROR(G29:G34,0))} | BJ31: {=SUMPRODUCT((E29:E34=BD31)*IFERROR(G29:G34,0))+SUMPRODUCT((H29:H34=BD31)*IFERROR(F29:F34,0))} | BK31: =BF31*3+BG31 | BL31: =1+SUMPRODUCT(((BK$30:BK$33>BK31)+(BK$30:BK$33=BK31)*(BM$30:BM$33>BM31)+(BK$30:BK$33=BK31)*(BM$30:BM$33=BM31)*(BN$30:BN$33>BN31)+(BK$30:BK$33=BK31)*(BM$30:BM$33=BM31)*(BN$30:BN$33=BN31)*(BO$30:BO$33>BO31)+(BK$30:BK$33=BK31)*(BM$30:BM$33=BM31)*(BN$30:BN$33=BN31)*(BO$30:BO$33=BO31)*((BI$30:BI$33-BJ$30:BJ$33)>(BI31-BJ31))+(BK$30:BK$33=BK31)*(BM$30:BM$33=BM31)*(BN$30:BN$33=BN31)*(BO$30:BO$33=BO31)*((BI$30:BI$33-BJ$30:BJ$33)=(BI31-BJ31))*(BI$30:BI$33>BI31)+(BK$30:BK$33=BK31)*(BM$30:BM$33=BM31)*(BN$30:BN$33=BN31)*(BO$30:BO$33=BO31)*((BI$30:BI$33-BJ$30:BJ$33)=(BI31-BJ31))*(BI$30:BI$33=BI31)*(ROW(BK$30:BK$33)<ROW(BK31)))*1) | BM31: {=SUMPRODUCT((E$29:E$34=BD31)*ISNUMBER(F$29:F$34)*ISNUMBER(G$29:G$34)*COUNTIFS(BD$30:BD$33,H$29:H$34,BK$30:BK$33,BK31)*((F$29:F$34>G$29:G$34)*3+(F$29:F$34=G$29:G$34)))+SUMPRODUCT((H$29:H$34=BD31)*ISNUMBER(F$29:F$34)*ISNUMBER(G$29:G$34)*COUNTIFS(BD$30:BD$33,E$29:E$34,BK$30:BK$33,BK31)*((G$29:G$34>F$29:F$34)*3+(F$29:F$34=G$29:G$34)))} | BN31: {=SUMPRODUCT((E$29:E$34=BD31)*ISNUMBER(F$29:F$34)*ISNUMBER(G$29:G$34)*COUNTIFS(BD$30:BD$33,H$29:H$34,BK$30:BK$33,BK31)*(F$29:F$34-G$29:G$34))+SUMPRODUCT((H$29:H$34=BD31)*ISNUMBER(F$29:F$34)*ISNUMBER(G$29:G$34)*COUNTIFS(BD$30:BD$33,E$29:E$34,BK$30:BK$33,BK31)*(G$29:G$34-F$29:F$34))} | BO31: {=SUMPRODUCT((E$29:E$34=BD31)*ISNUMBER(F$29:F$34)*ISNUMBER(G$29:G$34)*COUNTIFS(BD$30:BD$33,H$29:H$34,BK$30:BK$33,BK31)*F$29:F$34)+SUMPRODUCT((H$29:H$34=BD31)*ISNUMBER(F$29:F$34)*ISNUMBER(G$29:G$34)*COUNTIFS(BD$30:BD$33,E$29:E$34,BK$30:BK$33,BK31)*G$29:G$34)}
A32: 28 | B32: =TEXT((46193)+(20+4+GmtOffset)/24,"ddd") | C32: =TEXT((46193)+(20+4+GmtOffset)/24,"mmm d, yyyy") | D32: =TEXT((46193)+(20+4+GmtOffset)/24,"h:mm") | E32: Ecuador | H32: Curaçao | I32: E | K32: =INDEX(BD30:BD33,MATCH(2,BL30:BL33,0)) | L32: =INDEX(BE30:BE33,MATCH(2,BL30:BL33,0)) | M32: =INDEX(BF30:BF33,MATCH(2,BL30:BL33,0)) | N32: =INDEX(BG30:BG33,MATCH(2,BL30:BL33,0)) | O32: =INDEX(BH30:BH33,MATCH(2,BL30:BL33,0)) | P32: =INDEX(BI30:BI33,MATCH(2,BL30:BL33,0))&" - "&INDEX(BJ30:BJ33,MATCH(2,BL30:BL33,0)) | Q32: =INDEX(BK30:BK33,MATCH(2,BL30:BL33,0)) | W32: =IF(AND(ISNUMBER(T33),ISNUMBER(T34)),IF(T33>T34,S33,IF(T34>T33,S34,IF(NOT(AND(ISNUMBER(U33),ISNUMBER(U34))),"",IF(U33>U34,S33,IF(U34>U33,S34,IF(NOT(AND(ISNUMBER(V33),ISNUMBER(V34))),"",IF(V33>V34,S33,IF(V34>V33,S34,"")))))))),"W80") | BD32: Ivory Coast | BE32: {=SUMPRODUCT((((E29:E34=BD32)+(H29:H34=BD32))>0)*ISNUMBER(F29:F34)*ISNUMBER(G29:G34))} | BF32: {=SUMPRODUCT((E29:E34=BD32)*ISNUMBER(F29:F34)*ISNUMBER(G29:G34)*(F29:F34>G29:G34))+SUMPRODUCT((H29:H34=BD32)*ISNUMBER(F29:F34)*ISNUMBER(G29:G34)*(G29:G34>F29:F34))} | BG32: {=SUMPRODUCT((((E29:E34=BD32)+(H29:H34=BD32))>0)*ISNUMBER(F29:F34)*ISNUMBER(G29:G34)*(F29:F34=G29:G34))} | BH32: =BE32-BF32-BG32 | BI32: {=SUMPRODUCT((E29:E34=BD32)*IFERROR(F29:F34,0))+SUMPRODUCT((H29:H34=BD32)*IFERROR(G29:G34,0))} | BJ32: {=SUMPRODUCT((E29:E34=BD32)*IFERROR(G29:G34,0))+SUMPRODUCT((H29:H34=BD32)*IFERROR(F29:F34,0))} | BK32: =BF32*3+BG32 | BL32: =1+SUMPRODUCT(((BK$30:BK$33>BK32)+(BK$30:BK$33=BK32)*(BM$30:BM$33>BM32)+(BK$30:BK$33=BK32)*(BM$30:BM$33=BM32)*(BN$30:BN$33>BN32)+(BK$30:BK$33=BK32)*(BM$30:BM$33=BM32)*(BN$30:BN$33=BN32)*(BO$30:BO$33>BO32)+(BK$30:BK$33=BK32)*(BM$30:BM$33=BM32)*(BN$30:BN$33=BN32)*(BO$30:BO$33=BO32)*((BI$30:BI$33-BJ$30:BJ$33)>(BI32-BJ32))+(BK$30:BK$33=BK32)*(BM$30:BM$33=BM32)*(BN$30:BN$33=BN32)*(BO$30:BO$33=BO32)*((BI$30:BI$33-BJ$30:BJ$33)=(BI32-BJ32))*(BI$30:BI$33>BI32)+(BK$30:BK$33=BK32)*(BM$30:BM$33=BM32)*(BN$30:BN$33=BN32)*(BO$30:BO$33=BO32)*((BI$30:BI$33-BJ$30:BJ$33)=(BI32-BJ32))*(BI$30:BI$33=BI32)*(ROW(BK$30:BK$33)<ROW(BK32)))*1) | BM32: {=SUMPRODUCT((E$29:E$34=BD32)*ISNUMBER(F$29:F$34)*ISNUMBER(G$29:G$34)*COUNTIFS(BD$30:BD$33,H$29:H$34,BK$30:BK$33,BK32)*((F$29:F$34>G$29:G$34)*3+(F$29:F$34=G$29:G$34)))+SUMPRODUCT((H$29:H$34=BD32)*ISNUMBER(F$29:F$34)*ISNUMBER(G$29:G$34)*COUNTIFS(BD$30:BD$33,E$29:E$34,BK$30:BK$33,BK32)*((G$29:G$34>F$29:F$34)*3+(F$29:F$34=G$29:G$34)))} | BN32: {=SUMPRODUCT((E$29:E$34=BD32)*ISNUMBER(F$29:F$34)*ISNUMBER(G$29:G$34)*COUNTIFS(BD$30:BD$33,H$29:H$34,BK$30:BK$33,BK32)*(F$29:F$34-G$29:G$34))+SUMPRODUCT((H$29:H$34=BD32)*ISNUMBER(F$29:F$34)*ISNUMBER(G$29:G$34)*COUNTIFS(BD$30:BD$33,E$29:E$34,BK$30:BK$33,BK32)*(G$29:G$34-F$29:F$34))} | BO32: {=SUMPRODUCT((E$29:E$34=BD32)*ISNUMBER(F$29:F$34)*ISNUMBER(G$29:G$34)*COUNTIFS(BD$30:BD$33,H$29:H$34,BK$30:BK$33,BK32)*F$29:F$34)+SUMPRODUCT((H$29:H$34=BD32)*ISNUMBER(F$29:F$34)*ISNUMBER(G$29:G$34)*COUNTIFS(BD$30:BD$33,E$29:E$34,BK$30:BK$33,BK32)*G$29:G$34)}
